Workbook

Sheet 评测集
E1: 序号 | F1: 需求name | G1: 需求描述 | H1: A | I1: B | J1: C | K1: A vs B | L1: B vs C | M1: A vs C | N1: A vs B | O1: B vs C | P1: A vs C | Q1: A vs B | R1: B vs C | S1: A vs C
E2: C01 | F2: BankAccount | G2: The following description of a bank is given. Create a suitable class diagram from the given informal description. A bank manages any number of customers. The first name and last name of type String are stored for each customer. A bank consists of any number of branches. A customer has at least one and at most five accounts. Each account has an owner who is a customer of the bank. There are two basic types of accounts: Current accounts and savings accounts. Each account has an account number of type int and a current account balance of type double. Current accounts also have an overdraft limit of type double. | H2: @startuml class Bank { bankName: String } class Branch { branchName: String } class Customer { firstName: String lastName: String } abstract class Account { accountNumber: int balance: double } class CurrentAccount { overdraftLimit: double } class SavingsAccount { } Bank *-- "0..*" Branch: operatesBranch Bank --> "0..*" Customer: manages 'opposite bank Customer --> "1" Bank: bank Customer --> "1..5" Account: account 'opposite owner Account --> "1" Customer: owner 'opposite account CurrentAccount --|> Account SavingsAccount --|> Account @enduml | I2: @startuml class Bank class Branch class Customer { firstName : String lastName : String } abstract class Account { accountNumber : int balance : double } class CurrentAccount { overdraftLimit : double } class SavingsAccount Bank "1" -- "0..*" Customer : manages Bank "1" -- "0..*" Branch : consists of Customer "1" -- "1..5" Account : owns Account <|-- CurrentAccount Account <|-- SavingsAccount @enduml | J2: @startuml class Bank { } class Branch { } class Customer { - firstName: String - lastName: String } class Account { - accountNumber: int - balance: double } class CurrentAccount { - overdraftLimit: double } class SavingsAccount { } Bank "1" --- "0..*" Customer : manages Bank "1" *-- "0..*" Branch : consists of Customer "1" --- "1..5" Account : has Account "0..*" --- "1" Customer : owner CurrentAccount --|> Account SavingsAccount --|> Account @enduml | K2: D（平局） | L2: B | M2: A | N2: D（平局） | O2: B | P2: A | Q2: D（平局） | R2: C | S2: C
E3: C02 | F3: EUScienceConnect | G3: Recently, the European Union made funds available to set-up a cross-national research database that stores information concerning scientific articles of researchers working at institutions in the EU. Science Connect is the company that will be setting up this database. The system will store information regarding scientific staff (persons) and research institutions. Bot hare uniquely identified by a person ID and an institution code, respectively. The following is also recorded for each person: a phone number, keywords that identify his/her keys research topics and the institution he/she works for. A person can be an author of one article and a reviewer of another peer-reviewed article at the same time. The database will store the following information concerning scientific articles. Each scientific article is uniquely identified by a DOI (a document object identifier), and the system also stores the title and the authors of the article. In the case of multiple authors, the position of each author is stored. Science Connect distinguishes between two types of scientific articles: a scientific article is either a peer-reviewed paper or a technical report. The system stores the citation count of peer-reviewed papers and who reviewed the paper. A technical report is always published by a single research institution, while research institutions can of course publish multiple technical reports. The system keeps track of the different scientific publishers (e.g., IEE, Elsevier). A publisher is identified by name. A publisher can publish multiple journals to which research institutions can subscribe. These journals are given a name by the publisher (e.g., Decision Support Systems). Publishers can have journals with the same name as other publishers; e.g., it is possible that both IEE and Elsevier have a journal with the title Management Science. The impact factor, which measures the scientific impact of a journal is also stored. Finally, only peer-reviewed papers are published in journals, not technical reports. | H3: @startuml skinparam classAttributeIconSize 0 skinparam linetype ortho ' === Entities === class Person { personId : String phoneNumber : String researchKeywords : List<String> } class ResearchInstitution { institutionCode : String } class Publisher { name : String } class Journal { name : String impactFactor : double } ' === Article Hierarchy === abstract class ScientificArticle { doi : String title : String } class PeerReviewedPaper { citationCount : int } class TechnicalReport { } ' === Role / Authorship === class Authorship { position : int } ' === Relationships === ' Person works for ResearchInstitution Person --> "1" ResearchInstitution : worksFor 'opposite employs ResearchInstitution --> "*" Person : employs 'opposite worksFor ' Institution publishes Technical Reports ResearchInstitution --> "*" TechnicalReport : publishes 'opposite publishedBy TechnicalReport --> "1" ResearchInstitution : publishedBy 'opposite publishes ' Publisher issues Journals Publisher --> "*" Journal : issues 'opposite issuedBy Journal --> "1" Publisher : issuedBy 'opposite issues ' Institution subscribes to Journals ResearchInstitution --> "*" Journal : subscribesTo 'opposite subscribedBy Journal --> "*" ResearchInstitution : subscribedBy 'opposite subscribesTo ' ScientificArticle hierarchy ScientificArticle <|-- PeerReviewedPaper ScientificArticle <|-- TechnicalReport ' Authorship (links Person, ScientificArticle with position) Authorship --> "1" Person : authoredBy 'opposite authors Person --> "*" Authorship : authors 'opposite authoredBy Authorship --> "1" ScientificArticle : writes 'opposite authorships ScientificArticle --> "1..*" Authorship : authorships 'opposite writes ' PeerReviewedPaper is reviewed by Persons PeerReviewedPaper --> "*" Person : reviewedBy 'opposite reviews Person --> "*" PeerReviewedPaper : reviews 'opposite reviewedBy ' PeerReviewedPaper is published in a Journal PeerReviewedPaper --> "1" Journal : publishedIn 'opposite features Journal --> "*" PeerReviewedPaper : features 'opposite publishedIn @enduml | I3: @startuml class Person { personID : String phoneNumber : String keywords : Set<String> } class Institution { institutionCode : String } abstract class ScientificArticle { DOI : String title : String } class PeerReviewedPaper { citationCount : int } class TechnicalReport { } class Publisher { name : String } class Journal { name : String impactFactor : double } class Authorship { position : int } ScientificArticle <|-- PeerReviewedPaper ScientificArticle <|-- TechnicalReport Person "1" -- "1" Institution : worksFor Authorship -- "1..*" Person : author Authorship -- "1" ScientificArticle : article Person "0..*" -- "0..*" PeerReviewedPaper : reviews Institution "1" -- "0..*" TechnicalReport : publishes Publisher "1" -- "0..*" Journal : publishes Journal "1" -- "0..*" PeerReviewedPaper : publishesIn Institution "0..*" -- "0..*" Journal : subscribesTo @enduml | J3: @startuml class Person { - personID : String - phoneNumber : String - researchKeywords : String } class ResearchInstitution { - institutionCode : String } class ScientificArticle { - DOI : String - title : String } class PeerReviewedPaper { - citationCount : int } class TechnicalReport { } class Publisher { - name : String } class Journal { - name : String - impactFactor : float } class Authorship { - position : int } ScientificArticle <|-- PeerReviewedPaper ScientificArticle <|-- TechnicalReport Person "1" -- "1" ResearchInstitution : works for Person "1" -- "*" Authorship : authors through ScientificArticle "1" -- "*" Authorship : has author Person "1" -- "*" PeerReviewedPaper : reviews TechnicalReport "*" -- "1" ResearchInstitution : published by Publisher "1" *-- "*" Journal : publishes ResearchInstitution "*" -- "*" Journal : subscribes to PeerReviewedPaper "*" -- "1" Journal : published in @enduml | K3: A | L3: C | M3: A | N3: A | O3: C | P3: A | Q3: A | R3: B | S3: A
E4: C03 | F4: Cruise | G4: A cruise is organized by a specific provider, each provider has a name and a location. A cruise is identified by a number and a name and has a start and end date. A cruise requires many employees, each of whom has a name and a social security number. Several guests take part in a cruise, each guest has a name and it is also noted whether they are a VIP or not. A guest can, of course, also take several cruises. The name of each ship, the number of decks, the length of the ship, and the number of passengers are known. A ship can be used for different cruises. A cruise is booked through a travel agency. Each booking has a unique booking number and a booking date. A travel agency has a name and an address. A cruise always heads for a specific destination area, each destination area has a name, and the name of the sea is also noted. On a cruise, guests are offered several shows, each show has a title and a certain duration. A cruise has several guests, and each guest can participate in several cruises. Several tickets are issued for each cruise. A ticket belongs to exactly one cruise. A guest can have any number of tickets, but only one ticket per cruise. | H4: @startuml class Provider { name: String location: String } class Cruise { number: int name: String startDate: Date endDate: Date } class Employee { name: String socialSecurityNumber: String } class Guest { name: String isVip: boolean } class Ship { name: String numberOfDecks: int length: double numberOfPassengers: int } class TravelAgency { name: String address: String } class Booking { bookingNumber: int bookingDate: Date } class DestinationArea { name: String seaName: String } class Show { title: String duration: double } class Ticket { ticketNumber: int } Cruise --> "1" Provider: organizedBy 'opposite cruises Provider --> "*" Cruise: cruises 'opposite organizedBy Cruise --> "1..*" Employee: employs 'opposite cruisesWorked Employee --> "*" Cruise: cruisesWorked 'opposite employs Cruise --> "*" Guest: hosts 'opposite cruisesAttended Guest --> "*" Cruise: cruisesAttended 'opposite hosts Cruise --> "1" Ship: uses 'opposite cruisesServed Ship --> "*" Cruise: cruisesServed 'opposite uses Booking --> "1" Cruise: bookedFor 'opposite cruiseBookings Cruise --> "*" Booking: cruiseBookings 'opposite bookedFor Booking --> "1" TravelAgency: managedBy 'opposite bookingsHandled TravelAgency --> "*" Booking: bookingsHandled 'opposite managedBy Booking --> "1" Guest: bookedBy 'opposite guestBookings Guest --> "*" Booking: guestBookings 'opposite bookedBy Cruise --> "1" DestinationArea: headsFor 'opposite cruisesToDestination DestinationArea --> "*" Cruise: cruisesToDestination 'opposite headsFor Cruise --> "*" Show: offers 'opposite cruisesOfferingShow Show --> "*" Cruise: cruisesOfferingShow 'opposite offers Ticket --> "1" Cruise: issuedFor 'opposite tickets Cruise --> "*" Ticket: tickets 'opposite issuedFor Ticket --> "1" Guest: ownedBy 'opposite tickets Guest --> "*" Ticket: tickets 'opposite ownedBy @enduml | I4: @startuml class Provider { name : String location : String } class Cruise { number : String name : String startDate : Date endDate : Date } class Employee { name : String socialSecurityNumber : String } class Guest { name : String isVIP : Boolean } class Ship { name : String numberOfDecks : Integer length : Double passengerCapacity : Integer } class TravelAgency { name : String address : String } class Booking { bookingNumber : String bookingDate : Date } class DestinationArea { name : String seaName : String } class Show { title : String duration : Duration } class Ticket { ticketId : String } Cruise "1" -- "1" Provider : organizedBy Cruise "*" -- "*" Employee : requires Cruise "*" -- "*" Guest : participates Cruise "*" -- "1" Ship : uses Cruise "*" -- "1" DestinationArea : headsFor Cruise "1" -- "*" Show : offers Booking "*" -- "1" TravelAgency : bookedThrough Booking "*" -- "1" Cruise : books Booking "*" -- "1" Guest : bookedBy Ticket "*" -- "1" Cruise : issuedFor Ticket "*" -- "1" Guest : issuedTo @enduml | J4: @startuml class Provider { +name: String +location: String } class Cruise { +number: String +name: String +startDate: Date +endDate: Date } class Employee { +name: String +socialSecurityNumber: String } class Guest { +name: String +isVIP: Boolean } class Ship { +name: String +numberOfDecks: Integer +length: Double +numberOfPassengers: Integer } class TravelAgency { +name: String +address: String } class Booking { +bookingNumber: String +bookingDate: Date } class DestinationArea { +name: String +seaName: String } class Show { +title: String +duration: Integer } class Ticket { +ticketNumber: String } Provider "1" -- "0..*" Cruise Cruise "1" -- "0..*" Employee Cruise "1" -- "0..*" Guest Cruise "1" -- "0..*" Ticket Cruise "1" -- "1" Ship Cruise "1" -- "1" DestinationArea Cruise "1" -- "0..*" Show TravelAgency "1" -- "0..*" Booking Booking "1" -- "1" Ticket Guest "0..*" -- "0..*" Ticket Guest "0..*" -- "0..*" Cruise @enduml | K4: A | L4: B | M4: A | N4: A | O4: B | P4: A | Q4: D（平局） | R4: B | S4: A
E5: C04 | F5: House | G5: The address and building material (wood, brick, or concrete) of each house are stored. A house may have a basement, the size and name of which are stored. There are exactly two different types of basements: earth basements and concrete basements. The humidity level of earth basements is also stored. A special type of house is the semi-detached house. Additional information stored for this type of house includes whether it has its own garden and how many windows it has. Each semi-detached house has either two carports or a garage. For carports, information stored includes whether they are double carports and whether they have a flat roof; for garages, information stored includes whether they have an automatic garage door. Each house is serviced by several companies, whose names and addresses are stored. Whenever a company carries out a job in a house, the number of hours and the agreed price are recorded in a job log. | H5: @startuml class House { address: String buildingMaterial: BuildingMaterial } class SemiDetachedHouse { hasGarden: boolean windowCount: int } enum BuildingMaterial { WOOD BRICK CONCRETE } class Basement { name: String size: double } class EarthBasement { humidityLevel: double } class ConcreteBasement { } class ParkingFacility { } class CarportParking { } class GarageParking { } class Carport { isDouble: boolean hasFlatRoof: boolean } class Garage { hasAutomaticDoor: boolean } class Company { name: String address: String } class Job { hours: int agreedPrice: double jobDate: Date } House <|-- SemiDetachedHouse Basement <|-- EarthBasement Basement <|-- ConcreteBasement House *-- "0..1" Basement : basement SemiDetachedHouse *-- "1" ParkingFacility : parkingFacility ParkingFacility <|-- CarportParking ParkingFacility <|-- GarageParking CarportParking *-- "2" Carport : carports GarageParking *-- "1" Garage : garage House "1" -- "1..*" Company : servicingCompanies 'opposite servicedHouses Job --> "1" House : performedAt Job --> "1" Company : performedBy @enduml | I5: @startuml enum BuildingMaterial { WOOD BRICK CONCRETE } class House { address: String buildingMaterial: BuildingMaterial } abstract class Basement { size: float name: String } class EarthBasement { humidityLevel: float } class ConcreteBasement class SemiDetachedHouse { hasOwnGarden: boolean numberOfWindows: int } class Carport { isDouble: boolean hasFlatRoof: boolean } class Garage { hasAutomaticDoor: boolean } class Company { name: String address: String } class JobLog { hours: float price: float } House "1" -- "0..1" Basement Basement <|-- EarthBasement Basement <|-- ConcreteBasement House <|-- SemiDetachedHouse SemiDetachedHouse "1" -- "0..2" Carport SemiDetachedHouse "1" -- "0..1" Garage House "1" -- "*" JobLog Company "1" -- "*" JobLog House "*" -- "*" Company note right of SemiDetachedHouse Has either exactly two Carports or exactly one Garage. end note @enduml | J5: @startuml class House { +address: String +buildingMaterial: String } class Basement { +size: String +name: String } class EarthBasement { +humidityLevel: Float } class ConcreteBasement {} class SemiDetachedHouse { +hasGarden: Boolean +numberOfWindows: Integer } class Carport { +isDouble: Boolean +hasFlatRoof: Boolean } class Garage { +hasAutomaticDoor: Boolean } class Company { +name: String +address: String } class JobLog { +hours: Float +agreedPrice: Float } House <|-- SemiDetachedHouse House o-- Basement Basement <|-- EarthBasement Basement <|-- ConcreteBasement SemiDetachedHouse o-- Carport SemiDetachedHouse o-- Garage House o-- Company Company o-- JobLog @enduml | K5: A | L5: B | M5: A | N5: A | O5: B | P5: A | Q5: B | R5: D（平局） | S5: C
E6: C05 | F6: CelO | G6: Celebrations Organization System The CelO application helps families and groups of friends to organize birthday celebrations and other events. Organizers can keep track of which tasks have been completed and who attends. Attendees can indicate what they are bringing to the event. For a small event, there is typically one organizer, but larger events require several organizers. An organizer provides their first and last name, their email address (which is also used as their username), their postal address, their phone number, and their password. Furthermore, an organizer indicates the kind of event that needs to be planned by selecting from a list of events (e.g., birthday party, graduation party…) or creating a new kind of event. The start date/time and end date/time of the event must be specified as well as the occasion and location of the event. The location can again be selected from a list, or a new one can be created by specifying the name of the location and its address. An organizer then invites the attendees by entering their first and last names as well as their email addresses. Sometimes, an organizer is only managing the event but not attending the event. Sometimes, an organizer also attends the event. When an attendee receives the email invitation, the attendee can create an account (if they do not yet have an account) with a new password and their email address from the invitation as their username. Afterwards, the attendee can indicate whether they will attend the event, maybe will attend the event, or cannot attend the event. An organizer can view the invitation status of an event, e.g., how many attendees have replied or have not yet replied and who is coming for sure or maybe will be coming. When an organizer selects an event, an event-specific checklist is presented to the organizer. For example, a birthday party may have a task to bring a birthday cake. For each task on the checklist, an organizer can indicate that the task needs to be done, has been done, or is not applicable for the event. An organizer can also add new tasks to the list, which will then also be available for the next event. For example, an organizer can add to bring birthday candles to the list for a birthday party and this task will then be available for the next birthday party, too. An organizer can also designate a task on the checklist for attendees to accomplish. For example, an organizer can indicate that the birthday cake should be brought to the event by an attendee. If this is the case, then the list of tasks to be accomplished by attendees is shown to attendees that have confirmed their attendance to the event. An attendee can then select their tasks, so that the organizer can see who is bringing what to the event. | H6: @startuml enum RsvpStatus { PENDING CONFIRMED MAYBE DECLINED } enum TaskStatus { TO_DO DONE NOT_APPLICABLE } class User { firstName: String lastName: String email: String password: String } class Organizer { postalAddress: String phoneNumber: String } class Attendee { } class EventKind { name: String } class Location { name: String address: String } class Event { startDateTime: Date endDateTime: Date occasion: String } class TaskTemplate { description: String } class EventTask { status: TaskStatus isAttendeeDesignated: boolean } class Invitation { rsvpStatus: RsvpStatus } note right of User email serves as username end note User <|-- Organizer User <|-- Attendee EventKind "1" *-- "0..*" TaskTemplate : defines 'opposite eventKind EventKind "1" --> "0..*" Event : categorizes 'opposite kind Event "1" --> "1" Location : heldAt 'opposite hostedEvents Event "1" *-- "0..*" EventTask : schedules 'opposite event Event "1" *-- "0..*" Invitation : issues 'opposite event TaskTemplate "0..*" --> "0..*" EventTask : instantiates 'opposite template Invitation "*" --> "1" Attendee : sentTo 'opposite receivedInvitations Attendee "0..*" --> "0..*" EventTask : volunteersFor 'opposite volunteeredBy Organizer "1..*" --> "1..*" Event : manages 'opposite managedBy @enduml | I6: @startuml enum RsvpStatus { PENDING ATTENDING MAYBE DECLINED } enum TaskStatus { TODO DONE NOT_APPLICABLE } class User { firstName: String lastName: String email: String password: String } class Organizer { postalAddress: String phoneNumber: String } class Attendee { } class Event { startDate: DateTime endDate: DateTime occasion: String } class EventType { name: String } class Location { name: String address: String } class Invitation { invitedEmail: String rsvpStatus: RsvpStatus } class TaskTemplate { description: String } class EventTask { status: TaskStatus isForAttendees: Boolean } User <|-- Organizer User <|-- Attendee Event "1" -- "1..*" Organizer : organized by > Event "1" -- "1" EventType : has type > Event "1" -- "1" Location : held at > Event "1" -- "*" Invitation : has > Invitation "*" -- "0..1" Attendee : claimed by > EventType "1" -- "*" TaskTemplate : defines > Event "1" -- "*" EventTask : tracks > EventTask "*" -- "1" TaskTemplate : instantiates > EventTask "*" -- "0..1" Invitation : assigned to > @enduml | J6: @startuml enum InvitationStatus { Attending Maybe NotAttending NotReplied } enum TaskStatus { NeedsToBeDone HasBeenDone NotApplicable } class Person { firstName: String lastName: String email: String password: String } class Organizer { postalAddress: String phoneNumber: String } class Attendee { } class Event { occasion: String startDateTime: DateTime endDateTime: DateTime } class EventType { name: String } class Location { name: String address: String } class Task { description: String } class Invitation { status: InvitationStatus } class EventTask { status: TaskStatus isForAttendees: boolean } Person <|-- Organizer Person <|-- Attendee Organizer "1..*" organizes "0..*" Event Organizer "0..*" attends "0..*" Event Event *-- "0..*" Invitation Attendee "0..*" receives "0..*" Invitation Event -- "1" EventType Event -- "1" Location EventType *-- "0..*" Task Event *-- "0..*" EventTask EventTask -- "1" Task Attendee "0..*" selects "0..*" EventTask @enduml | K6: B | L6: B | M6: A | N6: B | O6: B | P6: C | Q6: A | R6: B | S6: A
E7: C06 | F7: TileOGame | G7: The Tile-O application first allows a game designer to design a board game and then allows players to play the game. Only one game can be played at a time and it cannot be paused or saved. The objective of the game is to find a hidden tile on the board. Two to four players take turns by moving their playing pieces along connected tiles based on the roll of a die. Each playing piece has a different color. A designer first defines the whole game including the layout of the game board. The designer places the tiles on the board and connects them with connection pieces. A tile can be connected to other tiles on its right side, left side, top side, and bottom side. At the most one tile can be connected on each side. In addition, the designer indicates the hidden tile, the starting positions of each player, as well as the location of action tiles. The designer also defines a deck of 32 action cards by choosing from the following predefined choices: (i) roll the die for an extra turn, (ii) connect two adjacent tiles with a connection piece from the pile of 32 spare connection pieces, (iii) remove a connection piece from the board and place it in the pile of spare connection pieces, (iv) move your playing piece to an arbitrary tile that is not your current tile, and (v) lose your next turn. Players take turns, with Player 1 starting the game, followed by Player 2, Player 3 (if applicable), and Player 4 (if applicable). The player whose turn it is rolls the die and them moves their playing piece along connected tiles. If the player lands on any tile, the color of the tile changes from white to black to indicate that the tile has been visited during the game. If the player lands on the hidden tile, the game ends and the player wins the game. If the player lands on an action tile, the player takes the first action card from the deck of action cards and follows the instructions on the action card. In addition, the action tile turns into a regular tile for a number of turns as specified by the game designer. Players do not know whether a tile is an action tile until a player lands on it. | H7: @startuml enum GameState { SETUP PLAYING FINISHED } enum ActionCardType { EXTRA_TURN CONNECT_TILES REMOVE_CONNECTION MOVE_TO_TILE LOSE_TURN } class Designer { name: String } class Player { name: String turnOrder: int isNextTurnLost: boolean } class PlayingPiece { color: String } class Die { roll(): int } class Game { state: GameState maxPlayers: int spareConnectionPieces: int currentPlayerIndex: int ' Singleton constraint: Only one game can be played at a time } class Board { width: int height: int } class Tile { posX: int posY: int isVisited: boolean isHidden: boolean isStartingPosition: boolean color: String isConnectedRight: boolean isConnectedLeft: boolean isConnectedTop: boolean isConnectedBottom: boolean } class ActionTile { turnsAsRegular: int turnsRemaining: int isRevealed: boolean } class Deck { } class ActionCard { cardType: ActionCardType } Designer --> "1" Game : designs Game "1" *-- "1" Board : board Game "1" *-- "1" Deck : deck Game "1" *-- "2..4" Player : players Game --> "1" Player : currentPlayer Game --> "0..1" Player : winner Game "1" *-- "1" Die : die Board "1" *-- "1..*" Tile : tiles Player "1" *-- "1" PlayingPiece : playingPiece Player --> "1" Tile : startingTile Player --> "1" Tile : currentTile Tile --> "0..1" Tile : rightTile 'opposite leftTile Tile --> "0..1" Tile : leftTile 'opposite rightTile Tile --> "0..1" Tile : topTile 'opposite bottomTile Tile --> "0..1" Tile : bottomTile 'opposite topTile Tile <|-- ActionTile Deck "1" *-- "32" ActionCard : cards @enduml | I7: @startuml enum Side { LEFT RIGHT TOP BOTTOM } enum TileColor { WHITE BLACK } enum PlayingPieceColor { RED BLUE GREEN YELLOW } enum ActionCardType { ROLL_EXTRA_TURN CONNECT_TILES REMOVE_CONNECTION MOVE_TO_ARBITRARY_TILE LOSE_TURN } class Game { - currentPlayer : Player - isGameEnded : boolean - winner : Player + startGame() : void + endGame(winner : Player) : void + nextTurn() : void + rollDie() : int } class GameDesigner { - name : String + designBoard() : void + placeTile(tile : Tile) : void + connectTiles(tile1 : Tile, tile2 : Tile, side : Side) : void + setHiddenTile(tile : Tile) : void + setStartingPosition(player : Player, tile : Tile) : void + setActionTile(tile : Tile) : void + defineActionDeck() : void } class Player { - name : String - currentTile : Tile - skippedTurns : int - playerNumber : int + move(steps : int) : void + executeActionCard(card : ActionCard) : void + skipTurn() : void } class PlayingPiece { - color : PlayingPieceColor + getColor() : PlayingPieceColor } class GameBoard { - width : int - height : int + addTile(tile : Tile, x : int, y : int) : void + removeTile(tile : Tile) : void + addConnection(connection : ConnectionPiece) : void + removeConnection(connection : ConnectionPiece) : void } abstract class Tile { - color : TileColor - x : int - y : int + markVisited() : void + isVisited() : boolean } class RegularTile { } class ActionTile { - cooldownTurns : int - currentCooldown : int + triggerAction() : void + decreaseCooldown() : void } class HiddenTile { + isFound() : boolean } class ConnectionPiece { - side1 : Side - side2 : Side + connect(tile1 : Tile, tile2 : Tile) : void + disconnect() : void } class ActionCard { - type : ActionCardType + execute(player : Player) : void } class Deck { - cards : ActionCard[] - cardsRemaining : int + drawCard() : ActionCard + shuffle() : void } class ConnectionPiecePile { - sparePieces : ConnectionPiece[] - piecesRemaining : int + takePiece() : ConnectionPiece + returnPiece(piece : ConnectionPiece) : void } class Die { - currentValue : int + roll() : int + getValue() : int } Game *-- GameBoard : has Game *-- Deck : has Game *-- ConnectionPiecePile : has Game *-- Die : has Game o--> GameDesigner : designed by Game --> Player : has players Game --> Player : current player Game --> Player : winner Player *- PlayingPiece : owns Player --> Tile : current tile GameBoard *- Tile : contains GameBoard *- ConnectionPiece : contains ConnectionPiece --> Tile : connects ConnectionPiece --> Tile : connects Deck *- ActionCard : contains ConnectionPiecePile *- ConnectionPiece : contains Tile <|-- RegularTile Tile <|-- ActionTile Tile <|-- HiddenTile @enduml | J7: @startuml enum GameState { DESIGNING PLAYING ENDED } enum TileColor { WHITE BLACK } enum Direction { RIGHT LEFT TOP BOTTOM } enum PieceColor { RED BLUE GREEN YELLOW } class Game { state: GameState turnNumber: int spareConnectionPieces: int start() endGame(winner: Player) nextTurn() } class GameDesigner { name: String } class Board { } class Tile { color: TileColor x: int y: int markVisited() isVisited(): boolean } class RegularTile class HiddenTile class ActionTile { cooldownTurns: int remainingCooldown: int isActive(): boolean deactivate() tickCooldown() } class ConnectionPiece class Player { name: String order: int skipNextTurn: boolean } class PlayingPiece { color: PieceColor } class Deck { drawCard(): ActionCard isEmpty(): boolean } abstract class ActionCard { execute(game: Game, player: Player) } class ExtraTurnCard class ConnectTilesCard class RemoveConnectionCard class MoveToTileCard class LoseTurnCard class Die { roll(): int } Game "1" *-- "1" Board : board Game "1" *-- "1" Deck : deck Game "1" *-- "1" Die : die Game "1" o-- "2..4" Player : players Game "1" --> "0..1" Player : currentPlayer Game "1" --> "1" GameDesigner : designedBy Board "1" *-- "1..*" Tile : tiles Board "1" --> "1" HiddenTile : hiddenTile Tile <|-- RegularTile Tile <|-- HiddenTile Tile <|-- ActionTile Tile "1" o-- "0..1" ConnectionPiece : rightConnection Tile "1" o-- "0..1" ConnectionPiece : leftConnection Tile "1" o-- "0..1" ConnectionPiece : topConnection Tile "1" o-- "0..1" ConnectionPiece : bottomConnection ConnectionPiece --> "2" Tile : connects Player "1" *-- "1" PlayingPiece : playingPiece Player --> "1" Tile : startingPosition PlayingPiece --> "1" Tile : currentTile Deck "1" *-- "32" ActionCard : cards ActionCard <|-- ExtraTurnCard ActionCard <|-- ConnectTilesCard ActionCard <|-- RemoveConnectionCard ActionCard <|-- MoveToTileCard ActionCard <|-- LoseTurnCard @enduml | K7: A | L7: C | M7: C | N7: A | O7: C | P7: C | Q7: B | R7: C | S7: C
E8: C07 | F8: SellingGoods | G8: This exercise teaches you to build and re-evaluate your solution in an iterative manner to handle changing requirements. First, create a class diagram for the use case described in STEP 1, and add attributes, event types, non-default FSMs and constraints if necessary. For each step, revise your model and add, remove or change elments where necessary. STEP 1 Your brand new company sells goods to local supermarkets. You want to create a simple information system to keep track of your stock, your customers and their orders. When you register a new customer, you enter their address and VAT number. To keep track of your stock, you want to be able to register the products you offer and the current stock of each product. Your customers' orders consist of one or more order lines, with each order line recording the quantity ordered of a particular product. To minimise the overhead of managing payments and deliveries for your small business, your customers are required to pay for their order in full before it is sent out for delivery. Similarly, orders are always shipped in their entirety to keep shipping simple. To ensure that you have the information you need for your accounts, you want to record when orders are paid for and shipped. At the end of each working day, you manually adjust the stock levels of your products in the system based on the orders placed that day. STEP 2 As your business grows, you start to offer more exclusive products that are not always available. To ensure customer satisfaction, you want to start organising deliveries on a line-by-line basis so that available products can be shipped immediately and unavailable products can be shipped later. Of course, you need to adapt your information system to keep track of partially shipped orders so that you can record which order lines have been shipped and which are still on the to-be-shipped list. Orders that have been fully shipped will also be marked so that you know that they can be removed from your watchlist. STEP 3 As your products become more popular, you start supplying larger supermarkets. These supermarkets sometimes have several warehouses that they use for different locations. You want to start keeping track of both the customer's head office address and the addresses where the orders are delivered. To further professionalise your business, you want to send invoices to your customers for their orders. Customers can now choose to pay the invoice directly when they place the order, or after the order has been delivered. An order should still be paid in full. STEP 4 As your business grows, keeping track of shipments on a line-by-line basis becomes too cumbersome. You would prefer to do this for each group of order lines that are shipped together. In addition, you have recently noticed some problems with the delivery service you use, as customers have informed you that some deliveries are missing or damaged. You want to gather more information about the deliveries in order to decide whether you should switch to another delivery service or start delivering yourself. To do this, you want to know the status of each delivery (remember that partial deliveries of one or more order lines are possible). You want to track a shipment as it is packed, shipped and received by the customer. | H8: @startuml skinparam classAttributeIconSize 0 class Address { - street : String - city : String - postalCode : String - country : String } class Customer { - customerId : String - name : String - vatNumber : String - headOfficeAddress : Address + register() + placeOrder() } class Warehouse { - warehouseId : String - address : Address } class Product { - productId : String - name : String - description : String - price : Money - currentStock : Integer + adjustStock(quantity : Integer) } class Order { - orderId : String - orderDate : Date - paidDate : Date - status : OrderStatus + markPaid() + markFullyShipped() } class OrderLine { - lineId : String - quantity : Integer - unitPrice : Money } class Invoice { - invoiceId : String - invoiceNumber : String - issueDate : Date - paidDate : Date - totalAmount : Money + sendToCustomer() } class Shipment { - shipmentId : String - shipmentDate : Date - receivedDate : Date - status : ShipmentStatus - trackingNumber : String + pack() + ship() + markReceived() } enum OrderStatus { PLACED PAID PARTIALLY_SHIPPED FULLY_SHIPPED } enum ShipmentStatus { PACKED SHIPPED RECEIVED } Customer "1" -- "1" Address : head office > Customer "1" *-- "0..*" Warehouse : operates > Warehouse "1" -- "1" Address : located at > Customer "1" *-- "0..*" Order : places > Order "1" -- "1" Warehouse : delivers to > Order "1" *-- "1" Invoice : generates > Order "1" *-- "1..*" OrderLine : contains > OrderLine "*" -- "1" Product : refers to > Order "1" *-- "0..*" Shipment : ships > Shipment "1" o-- "1..*" OrderLine : groups > @enduml | I8: @startuml enum PaymentTiming { ON_ORDER ON_DELIVERY } enum PaymentStatus { UNPAID PAID } enum ShipmentStatus { PACKED SHIPPED RECEIVED MISSING DAMAGED } class Customer { vatNumber: String } class Address { street: String city: String postalCode: String } class Product { name: String currentStock: Integer } class Order { orderDate: Date paymentStatus: PaymentStatus paymentTiming: PaymentTiming } class OrderLine { orderedQuantity: Integer shippedQuantity: Integer } class Invoice { invoiceDate: Date totalAmount: Decimal isPaid: Boolean } class Shipment { shipmentDate: Date status: ShipmentStatus } class ShipmentLine { shippedQuantity: Integer } Customer "1" -- "1" Address : headOffice Customer "1" -- "0..*" Address : deliveryWarehouses Customer "1" -- "0..*" Order : places Order "1" -- "1" Address : deliveredTo Order "1" -- "1..*" OrderLine : contains Order "1" -- "0..1" Invoice : has Order "1" -- "0..*" Shipment : fulfilledBy OrderLine "0..*" -- "1" Product : refersTo Shipment "1" -- "1..*" ShipmentLine : contains ShipmentLine "0..*" -- "1" OrderLine : refersTo @enduml | J8: @startuml class Company { name: String } class Customer { vatNumber: String } class DeliveryAddress { address: String } class Product { name: String currentStock: int } class Order { orderDate: Date paymentStatus: PaymentStatus paymentMethod: PaymentMethod shippingStatus: ShippingStatus } class OrderLine { quantityOrdered: int } class Invoice { invoiceNumber: String issueDate: Date totalAmount: double } class Shipment { trackingNumber: String shipmentDate: Date status: ShipmentStatus } class Delivery { deliveryDate: Date conditionNotes: String status: DeliveryStatus } enum PaymentStatus { PENDING PAID } enum ShippingStatus { NOT_SHIPPED PARTIALLY_SHIPPED FULLY_SHIPPED } enum DeliveryStatus { PACKED SHIPPED RECEIVED DAMAGED MISSING } enum ShipmentStatus { PACKED SHIPPED RECEIVED } enum PaymentMethod { DIRECT POST_DELIVERY } Company "1" --> "*" Customer : registers 'opposite company Company "1" --> "*" Product : stocks 'opposite company Customer "1" --> "*" DeliveryAddress : hasWarehouses 'opposite customer Customer "1" --> "*" Order : places 'opposite customer Customer "1" --> "1" DeliveryAddress : headOfficeAddress 'opposite headOfficeCustomer Order "1" --> "1" DeliveryAddress : deliveredTo 'opposite deliveryOrder Order "1" --> "*" OrderLine : consistsOf 'opposite order Order "1" --> "1" Invoice : hasInvoice 'opposite order Invoice "*" --> "1" Customer : issuedTo 'opposite invoices OrderLine "*" --> "1" Product : references 'opposite orderLines Shipment "1" --> "*" Delivery : trackedAs 'opposite shipment Shipment "1" --> "*" OrderLine : ships 'opposite shipment Delivery "*" --> "*" OrderLine : deliversTo 'opposite deliveredIn Order "1" --> "*" Shipment : fulfilledBy 'opposite order @enduml | K8: D（平局） | L8: B | M8: A | N8: B | O8: B | P8: A | Q8: D（平局） | R8: B | S8: A
E9: C08 | F9: University | G9: A university consists of several faculties, which are made up of various institutes. Each faculty and institute has a name. The address of each institute is known. Each faculty is headed by a dean, who is an employee of the university. The total number of employees is known. Employees have a social security number, a name, and an email address. A distinction is made between research and administrative staff. Research assistants (RA) are assigned to at least one institute. The field of research of each RA is known. In addition, RAs can be involved in projects for a certain number of hours, whereby the name, start and end dates of the projects are known. Some RAs teach courses. In this case, they are referred to as lecturers. Courses have a unique number (ID), a name and a weekly duration in hours. | H9: @startuml class University { name : String totalEmployees : int } class Faculty { name : String } class Institute { name : String address : String } University *-- "1..*" Faculty : faculties Faculty *-- "1..*" Institute : institutes class Employee { socialSecurityNumber : String name : String email : String } class ResearchStaff { } class AdministrativeStaff { } class ResearchAssistant { fieldOfResearch : String } class Lecturer { } Employee <|-- ResearchStaff Employee <|-- AdministrativeStaff ResearchStaff <|-- ResearchAssistant ResearchAssistant <|-- Lecturer class Project { name : String startDate : Date endDate : Date } class ProjectInvolvement { hours : int } class Course { id : int name : String weeklyDurationHours : double } Faculty --> "1" Employee : dean 'opposite headedFaculty Employee --> "0..1" Faculty : headedFaculty 'opposite dean ResearchAssistant --> "1..*" Institute : assignedInstitutes 'opposite researchAssistants Institute --> "*" ResearchAssistant : researchAssistants 'opposite assignedInstitutes ResearchAssistant --> "0..*" ProjectInvolvement : involvements 'opposite researchAssistant ProjectInvolvement --> "1" Project : project 'opposite involvements Lecturer --> "0..*" Course : taughtCourses 'opposite lecturers Course --> "*" Lecturer : lecturers 'opposite taughtCourses University --> "*" Employee : employees 'opposite university Employee --> "1" University : university 'opposite employees @enduml | I9: @startuml class University { - totalEmployees : int } class Faculty { - name : String } class Institute { - name : String - address : String } class Employee { - socialSecurityNumber : String - name : String - email : String } class AdministrativeStaff { } class ResearchStaff { - fieldOfResearch : String } class Lecturer { } class Project { - name : String - startDate : Date - endDate : Date } class Course { - id : String - name : String - weeklyDurationHours : int } University "1" *-- "many" Faculty : contains Faculty "1" *-- "many" Institute : contains Faculty "1" --> "1" Employee : has dean Employee <|-- AdministrativeStaff Employee <|-- ResearchStaff ResearchStaff <|-- Lecturer ResearchStaff "many" --> "1..*" Institute : assigned to ResearchStaff "many" --> "0..*" Project : involved in (hours : int) Lecturer "many" --> "0..*" Course : teaches @enduml | J9: @startuml class University { totalEmployees : int } class Faculty { name : String } class Institute { name : String } class Address { street : String city : String zipCode : String } abstract class Employee { socialSecurityNumber : String name : String email : String } class AdministrativeStaff class ResearchStaff class ResearchAssistant { fieldOfResearch : String } class Lecturer class Project { name : String startDate : Date endDate : Date } class Course { id : String name : String weeklyDurationHours : int } class ProjectInvolvement { hours : int } University "1" *-- "0..*" Faculty Faculty "1" *-- "0..*" Institute Faculty "1" --> "1" Employee : dean Institute "1" *-- "1" Address Employee <|-- AdministrativeStaff Employee <|-- ResearchStaff ResearchStaff <|-- ResearchAssistant ResearchAssistant <|-- Lecturer ResearchAssistant "1..*" -- "0..*" Institute : assigned to ResearchAssistant "0..*" -- "0..*" ProjectInvolvement Project "1" -- "0..*" ProjectInvolvement Lecturer "0..*" -- "0..*" Course : teaches @enduml | K9: A | L9: C | M9: D（平局） | N9: A | O9: C | P9: A | Q9: A | R9: C | S9: D（平局）
E10: C09 | F10: TeamSportsScoutingSystem | G10: The Team Sports Scouting System is used by various employees of the club, including the head coach, the director of the club and the scouts. It is the role of the head coach to identify designated player profiles for future signings, which includes designated target positions for a player (e.g. GK for goalkeeper, LB for left back, etc.), and other player attributes (identified by a name and a value). Scouts may note players on a long list who seem to match a designated target profile at any time. This long list is periodically evaluated by the head scout when setting up scouting assignments for his team to investigate a specific player more thoroughly. As the completion of a scouting assignment, the scout submits a scouting report about the player, which includes the pros and cons of the player as well as a recommendation (e.g. key player, first team player, reserve team player, prospective player, not a good signing). After comparing first scouting results for a designated player profile, the head coach and the head scout decide upon which players to move to the short list. Several other rounds of scouting can be carried out for each short-listed player as part of scouting assignments – some of which is carried out by the head scout himself. If a player is finally recommended for signing by the head scout, the director makes an official offer for the player. | H10: @startuml enum Position { GK CB LB RB CDM CM CAM LW RW ST } enum Recommendation { KEY_PLAYER FIRST_TEAM RESERVE_TEAM PROSPECTIVE NOT_GOOD_SIGNING } enum ScoutingState { LONG_LIST UNDER_INVESTIGATION SHORT_LIST RECOMMENDED OFFER_MADE } class Employee { employeeId: int name: String } class HeadCoach { } class Director { } class Scout { } class HeadScout { } class Player { playerId: int name: String currentClub: String } class TargetProfile { profileId: int name: String targetPositions: List<Position> } class Attribute { name: String value: String } class LongListEntry { entryId: int entryDate: Date notes: String } class ScoutingAssignment { assignmentId: int description: String assignmentDate: Date deadline: Date } class ScoutingReport { reportId: int pros: String cons: String recommendation: Recommendation submissionDate: Date } class ScoutingRecord { currentState: ScoutingState } class Offer { offerId: int amount: double offerDate: Date status: String } Employee <|-- HeadCoach Employee <|-- Director Employee <|-- Scout Scout <|-- HeadScout HeadCoach --> "*" TargetProfile: defines TargetProfile *-- "*" Attribute: attributes Scout --> "*" LongListEntry: logs LongListEntry --> "1" Player: player LongListEntry --> "1" TargetProfile: matchedProfile ScoutingRecord --> "*" LongListEntry: initialEntries ScoutingRecord --> "*" ScoutingAssignment: assignments ScoutingAssignment --> "1" Player: assignedPlayer ScoutingAssignment --> "1" Scout: assignedScout Scout --> "*" ScoutingReport: submits ScoutingAssignment --> "1" ScoutingReport: produces ScoutingReport --> "1" ScoutingAssignment: fulfills 'opposite produces HeadCoach --> "*" ScoutingRecord: manages HeadScout --> "*" ScoutingRecord: evaluates ScoutingRecord --> "1" Player: tracks ScoutingRecord --> "1" TargetProfile: alignedWith Director --> "*" Offer: makes Offer --> "1" Player: offeredPlayer Offer --> "1" ScoutingRecord: basedOn @enduml | I10: @startuml enum Recommendation { KEY_PLAYER FIRST_TEAM_PLAYER RESERVE_TEAM_PLAYER PROSPECTIVE_PLAYER NOT_A_GOOD_SIGNING } enum AssignmentStatus { PENDING IN_PROGRESS COMPLETED } class Employee { + id: UUID + name: String } class HeadCoach class Director class Scout class HeadScout Employee <|-- HeadCoach Employee <|-- Director Employee <|-- Scout Scout <|-- HeadScout class TargetProfile { + id: UUID + description: String } class TargetPosition { + code: String + name: String } class ProfileAttribute { + name: String + value: String } class Player { + id: UUID + name: String + currentClub: String } class LongListEntry { + dateAdded: Date + notes: String } class ShortListEntry { + dateAdded: Date } class ScoutingAssignment { + id: UUID + status: AssignmentStatus + deadline: Date } class ScoutingReport { + id: UUID + pros: String + cons: String + recommendation: Recommendation } class ContractOffer { + id: UUID + amount: Decimal + date: Date } HeadCoach "1" -- "0..*" TargetProfile : identifies > TargetProfile "1" -- "1..*" TargetPosition : targets > TargetProfile "1" -- "0..*" ProfileAttribute : defines > Scout "1" -- "0..*" LongListEntry : creates > LongListEntry "0..*" -- "1" Player : evaluates > LongListEntry "0..*" -- "1" TargetProfile : matches > HeadScout "1" -- "0..*" ScoutingAssignment : creates > ScoutingAssignment "0..*" -- "1" Scout : assigned to > ScoutingAssignment "0..*" -- "1" Player : investigates > Scout "1" -- "0..*" ScoutingReport : submits > ScoutingReport "1" -- "1" ScoutingAssignment : completes > HeadCoach "1" -- "0..*" ShortListEntry : approves > HeadScout "1" -- "0..*" ShortListEntry : approves > ShortListEntry "0..*" -- "1" Player : includes > ShortListEntry "0..*" -- "1" TargetProfile : fulfills > Director "1" -- "0..*" ContractOffer : makes > ContractOffer "0..*" -- "1" Player : offered to > @enduml | J10: @startuml class Team { + name : String } class Employee { + name : String + role : String } class Player { + id : String + name : String + targetPosition : String + playerStatus : String } class PlayerProfile { + targetPosition : String + playerAttributes : List<Attribute> } class Attribute { + name : String + value : String } class Scout { + name : String } class ScoutingAssignment { + assignmentDate : Date + status : String + shortList : List<Player> + scoutingResults : List<String> } class ScoutingReport { + pros : List<String> + cons : List<String> + recommendation : String + decision : String + relatedAssignment : ScoutingAssignment } class Director { + name : String } class HeadCoach { + name : String } class HeadScout { + name : String } Team --> "*" Employee : employs Employee --|> HeadCoach Employee --|> Director Employee --|> Scout Employee --|> HeadScout HeadCoach --> "*" PlayerProfile : identifies Scout --> "*" Player : notes HeadScout --> "*" ScoutingAssignment : evaluates Scout --> "*" ScoutingReport : submits HeadCoach --> "*" PlayerProfile : decides HeadScout --> "*" PlayerProfile : recommends Director --> "*" Player : makesOffer ScoutingAssignment --> "*" PlayerProfile : investigates ScoutingReport --> "1" relatedAssignment : linkedAssignment ScoutingReport --> "1" PlayerProfile : reportsOn PlayerProfile --> "*" Player : profiles PlayerProfile --> "*" Attribute : hasAttributes @enduml | K10: B | L10: B | M10: A | N10: B | O10: B | P10: A | Q10: D（平局） | R10: B | S10: A
