Workbook

Sheet 实验结果
A1: 需求name | B1: 需求描述 | C1: 类别 | D1: 指标类别 | E1: 位置 | F1: 提示词 | G1: 生产模式设置 | H1: 基座模型设置 | I1: 输出结果 | J1: 最终结果 | K1: 实际结果 | L1: 人工打标 | M1: 一致性
A2: AdvancedAlloyCompositionOptimization | B2: The Advanced Alloy Composition Optimization system supports research and industrial processes for developing high-performance metal alloys. The core unit of production is an Alloy Batch, created on a specific date, which contains multiple Material Specimens. Each specimen is defined by its density and surface finish, possesses a base Element Composition describing its chemical makeup, and has a current Phase Distribution detailing the fractions of target phases such as Austenite, Ferrite, Martensite, or Pearlite. Specimens can be analyzed to determine their current phase, classify grain structure, and annotate any defects. To achieve desired material properties, the system utilizes an Experiment Planner that generates Heat Treatment Profiles. These profiles, identified by name and quenching status, define processing steps and are validated before use. The planning process relies on a Phase Diagram Calculator to identify stable phases and check for equilibrium states. During execution, a Process Controller manages Thermal Analysis Runs, utilizing a Thermal Cycle Simulator to model cooling rates and peak temperatures while adhering to strict Safety Protocols that include emergency stop capabilities and temperature limits. Each thermal analysis run applies a specific profile. Data collection is organized under Research Projects, led by a principal investigator with a defined budget and associated design constraints. Projects encompass Experimental Datasets that verify data integrity, filter results, and store generated outcomes. These datasets aggregate Spectroscopy Data, which records wavelengths and emission intensities to detect phases and analyze elemental composition. Microstructure Analysis correlates specimen samples with spectroscopic data to refine phase distributions, utilizing the Phase Diagram Calculator as a reference. Furthermore, Stress Test Runners perform destructive or non-destructive tensile tests on specimens to generate Performance Metrics regarding load and increment steps. These metrics feed into Optimization Results that track convergence and recommend optimal element compositions. The system ensures adherence to engineering and legal standards through Design Constraints and Regulatory Standards, which specify limit values and effective dates to check specimen compliance. A Compliance Archive stores Batch Records, linking regulatory standards to specific batches; each record documents the primary phase, quality status, and the associated alloy batch. Operational support includes a Cost Estimator for calculating raw material expenses based on composition, a Supplier Network for finding vendors meeting design constraints, and a Quality Assurance module where certified inspectors approve batches. Finally, a Report Generator compiles performance metrics and quality assurance sources into summary reports in various formats. | C2: A vs B | D2: faithfulness | E2: l2r | F2: You are a professional software engineer with expertise across multiple domains. You evaluate UML class diagrams from the perspective of real-world software design, applying domain knowledge and engineering best practices alongside the provided scoring criteria. Please evaluate the two diagrams (Model 1, Model 2) based on the provided requirement and scoring criteria. # Criteria **CRITICAL INSTRUCTION**: You MUST evaluate the responses against EACH AND EVERY criterion listed in the "Specific Instructions" one by one. DO NOT aggregate, summarize, or skip any criterion. **Specific Instructions**: - Ensure that the design aligns with the given requirement strictly, achieving all the functionalities based on the requirements without making any hallucinations and additions. Ensure that the conceptual classes and their relationships accurately represent the essentials outlined in the requirement. This includes a detailed focus on the associations between classes, their cardinalities, and the types of relationships such as inheritance, aggregation, and composition. Clarity in class names and the optional inclusion of attributes are key for aligning with the project's vision. # Evaluation Guidelines ## General Rules - Consider only UML class diagram semantics (e.g., classes, attributes, associations, multiplicities, generalisation, composition/aggregation). - Ignore layout, styling, skinparams, comments, and notes. - If the response is incomplete or misses any required key component, regard it as a bad one. - Give credit for semantic clarity, but not for layout, comments, visibility markers, or other presentation-only differences. ## Forbidden Penalties (Strictly Enforced) You MUST NOT deduct points, lower scores, or claim a model is "worse", "complex", or "less practical" based on ANY of the following: 1. **Association Styles**: Using two opposite unidirectional associations (e.g., `A --> B` and `B --> A`) instead of one single bidirectional line (e.g., `A -- B`). They are 100% semantically equivalent. Treat opposite-direction associations as equivalent unless role labels, multiplicities, or navigability contradict the requirements. 2. **PlantUML Comments**: Using single-quote comments (e.g., `'opposite bank`) at the end of lines. These are standard tooling annotations — ignore them for scoring unless they obscure or contradict the relation meaning. 3. **Primitive Types**: Using common aliases for types (e.g., `int` instead of `Integer`, `str` instead of `String`, `boolean` instead of `Boolean`). Lowercase or language-flavored spellings are acceptable. 4. **Equivalent Multiplicity Literals**: Using `*` instead of `0..*`, or `1` instead of `1..1`. These pairs are semantically identical. 5. **Optional Abstractness**: Marking or not marking a superclass as `abstract` when the requirement does not say whether direct instances are allowed. Do not reward either style without requirement evidence. These forbidden factors must not appear as negative evidence under any criterion and must not affect criterion scores or the final choice. ## Evidence & Calibration Requirements - For every criterion you discuss, cite concrete evidence from both models. Quote or closely paraphrase the relevant class, attribute, association, multiplicity, inheritance, note, or missing element. - Do not claim a class, attribute, or association is missing when a synonymous or directly related element is present. If the present element is indirect, vague, over-constrained, or semantically weak, state that precise weakness instead. - Distinguish omissions from contradictions. Missing a hard constraint is usually less severe than explicitly modeling the opposite or an invalid multiplicity. - Do not reward a simpler model merely for being shorter if the more detailed model uses traceable intermediate workflow/concept classes required for domain reasoning. - Do not penalize a detailed model merely for using transparent refinements such as `Definition`, `Placement`, `Entry`, `Session`, `State`, `Record`, `Assignment`, `Arrangement`, or `Need` when the base requirement term remains recognizable. - Do not reward extra identifiers, timestamps, statuses, classes, or implementation-oriented detail unless they improve coverage of a stated requirement fact. - Text introduced by `e.g.`, `for example`, or `such as` gives examples, not a complete enumeration, unless the requirement explicitly declares a closed list. - Keep UML/PlantUML standards separate from domain accuracy. Domain-faithfulness problems, wrong business multiplicities, missing constraints, or vague semantics belong under the domain criteria, not UML standards, unless they make the notation invalid or unreadable. - When evaluating position bias, remember that Model 1 and Model 2 may be swapped in a second pass. Use only the content under each model block, not assumptions from prior comparisons or labels. # Requirement ``` The Advanced Alloy Composition Optimization system supports research and industrial processes for developing high-performance metal alloys. The core unit of production is an Alloy Batch, created on a specific date, which contains multiple Material Specimens. Each specimen is defined by its density and surface finish, possesses a base Element Composition describing its chemical makeup, and has a current Phase Distribution detailing the fractions of target phases such as Austenite, Ferrite, Martensite, or Pearlite. Specimens can be analyzed to determine their current phase, classify grain structure, and annotate any defects. To achieve desired material properties, the system utilizes an Experiment Planner that generates Heat Treatment Profiles. These profiles, identified by name and quenching status, define processing steps and are validated before use. The planning process relies on a Phase Diagram Calculator to identify stable phases and check for equilibrium states. During execution, a Process Controller manages Thermal Analysis Runs, utilizing a Thermal Cycle Simulator to model cooling rates and peak temperatures while adhering to strict Safety Protocols that include emergency stop capabilities and temperature limits. Each thermal analysis run applies a specific profile. Data collection is organized under Research Projects, led by a principal investigator with a defined budget and associated design constraints. Projects encompass Experimental Datasets that verify data integrity, filter results, and store generated outcomes. These datasets aggregate Spectroscopy Data, which records wavelengths and emission intensities to detect phases and analyze elemental composition. Microstructure Analysis correlates specimen samples with spectroscopic data to refine phase distributions, utilizing the Phase Diagram Calculator as a reference. Furthermore, Stress Test Runners perform destructive or non-destructive tensile tests on specimens to generate Performance Metrics regarding load and increment steps. These metrics feed into Optimization Results that track convergence and recommend optimal element compositions. The system ensures adherence to engineering and legal standards through Design Constraints and Regulatory Standards, which specify limit values and effective dates to check specimen compliance. A Compliance Archive stores Batch Records, linking regulatory standards to specific batches; each record documents the primary phase, quality status, and the associated alloy batch. Operational support includes a Cost Estimator for calculating raw material expenses based on composition, a Supplier Network for finding vendors meeting design constraints, and a Quality Assurance module where certified inspectors approve batches. Finally, a Report Generator compiles performance metrics and quality assurance sources into summary reports in various formats. ``` # Model 1 ``` @startuml ' Enumerations enum SurfaceFinish { POLISHED ROUGH MACHINED AS_CAST } enum PhaseType { AUSTENITE FERRITE MARTENSITE PEARLITE } enum TestType { DESTRUCTIVE NON_DESTRUCTIVE } enum QualityStatus { APPROVED REJECTED PENDING } enum RunState { INITIALIZED HEATING HOLDING COOLING COMPLETED EMERGENCY_STOP } enum ReportFormat { PDF CSV JSON HTML } ' Domain Classes class AlloyBatch { batchId: String creationDate: Date name: String } class MaterialSpecimen { specimenId: String density: double surfaceFinish: SurfaceFinish grainStructure: String defectAnnotation: String } class ElementComposition { elementName: String percentage: double } class PhaseDistribution { phaseType: PhaseType fraction: double } class ExperimentPlanner { plannerId: String name: String } class HeatTreatmentProfile { profileId: String name: String quenchingStatus: boolean isValidated: boolean } class ProcessingStep { stepOrder: int targetTemperature: double durationMinutes: int description: String } class PhaseDiagramCalculator { calculatorId: String name: String equilibriumState: boolean stablePhases: String } class ProcessController { controllerId: String name: String } class ThermalAnalysisRun { runId: String currentState: RunState peakTemperature: double coolingRate: double startTime: Date endTime: Date } class ThermalCycleSimulator { simulatorId: String name: String } class SafetyProtocol { protocolId: String maxTemperatureLimit: double minTemperatureLimit: double emergencyStopEnabled: boolean } class ResearchProject { projectId: String projectName: String principalInvestigator: String budget: double } class ExperimentalDataset { datasetId: String name: String dataIntegrityVerified: boolean creationDate: Date filterCriteria: String resultsFiltered: boolean } class SpectroscopyData { dataId: String wavelength: double emissionIntensity: double detectedPhase: PhaseType timestamp: Date } class MicrostructureAnalysis { analysisId: String correlatedPhase: PhaseType refinedFraction: double description: String } class StressTestRunner { runnerId: String name: String } class StressTestRun { testId: String testType: TestType maxLoad: double incrementStep: double timestamp: Date } class PerformanceMetric { metricId: String loadValue: double incrementValue: double stressValue: double strainValue: double } class OptimizationResult { resultId: String convergenceTracked: boolean iterationCount: int recommendedComposition: String } class DesignConstraint { constraintId: String constraintName: String limitValue: double effectiveDate: Date } class RegulatoryStandard { standardId: String standardName: String limitValue: double effectiveDate: Date } class ComplianceArchive { archiveId: String archiveDate: Date } class BatchRecord { recordId: String primaryPhase: PhaseType qualityStatus: QualityStatus recordDate: Date } class CostEstimator { estimatorId: String name: String } class CostEstimation { estimationId: String totalCost: double currency: String calculationDate: Date } class SupplierNetwork { networkId: String name: String } class Supplier { supplierId: String name: String meetsConstraints: boolean contactInfo: String } class QualityAssurance { moduleId: String name: String } class QualityAssuranceReview { reviewId: String inspectorName: String inspectorCertified: boolean approvalDate: Date isApproved: boolean } class ReportGenerator { generatorId: String name: String } class SummaryReport { reportId: String title: String format: ReportFormat generationDate: Date } ' Associations and Compositions AlloyBatch "1" *-- "1..*" MaterialSpecimen: contains specimens MaterialSpecimen "1" *-- "1..*" ElementComposition: base composition MaterialSpecimen "1" *-- "1..*" PhaseDistribution: current phases ExperimentPlanner "1" --> "1..*" HeatTreatmentProfile: generates profiles HeatTreatmentProfile "1" *-- "1..*" ProcessingStep: defined steps PhaseDiagramCalculator "1" --> "*" HeatTreatmentProfile: references for planning PhaseDiagramCalculator "1" --> "*" MicrostructureAnalysis: references for analysis ProcessController "1" --> "1..*" ThermalAnalysisRun: manages runs ProcessController "1" --> "1" ThermalCycleSimulator: utilizes simulator ProcessController "1" --> "1..*" SafetyProtocol: adheres to protocols ThermalCycleSimulator "1" --> "*" ThermalAnalysisRun: simulates ThermalAnalysisRun "*" --> "1" HeatTreatmentProfile: applies profile ResearchProject "1" *-- "1..*" ExperimentalDataset: encompassed datasets ResearchProject "1" --> "1..*" DesignConstraint: associated constraints ExperimentalDataset "1" *-- "*" SpectroscopyData: aggregated data ExperimentalDataset "1" *-- "*" MicrostructureAnalysis: included analyses MicrostructureAnalysis "*" --> "1" MaterialSpecimen: correlates specimen MicrostructureAnalysis "*" --> "1" SpectroscopyData: correlates spectroscopic data StressTestRunner "1" --> "1..*" StressTestRun: performs tests MaterialSpecimen "1" --> "*" StressTestRun: tested in StressTestRun "1" *-- "1..*" PerformanceMetric: generated metrics PerformanceMetric "*" --> "1" OptimizationResult: feeds into ComplianceArchive "1" *-- "1..*" BatchRecord: stored records BatchRecord "*" --> "1" AlloyBatch: documents batch BatchRecord "*" --> "1..*" RegulatoryStandard: linked standards CostEstimator "1" --> "*" AlloyBatch: estimates costs for CostEstimator "1" --> "*" ElementComposition: calculates based on CostEstimator "1" --> "*" CostEstimation: produces estimations AlloyBatch "1" --> "1" CostEstimation: estimated by SupplierNetwork "1" --> "*" Supplier: finds vendors SupplierNetwork "1" --> "*" DesignConstraint: matches constraints QualityAssurance "1" --> "*" QualityAssuranceReview: conducts reviews AlloyBatch "1" --> "*" QualityAssuranceReview: reviewed in ReportGenerator "1" --> "*" SummaryReport: compiles reports ReportGenerator "*" --> "*" PerformanceMetric: compiles from metrics ReportGenerator "*" --> "*" QualityAssuranceReview: compiles from reviews @enduml ``` # Model 2 ``` @startuml skinparam classAttributeIconSize 0 hide empty members class AlloyBatch { creationDate: Date } class MaterialSpecimen { density: Float surfaceFinish: String } class ElementComposition { chemicalMakeup: Map } class PhaseDistribution { austenite: Float ferrite: Float martensite: Float pearlite: Float } class ExperimentPlanner { generateProfile() } class HeatTreatmentProfile { name: String quenchingStatus: Boolean processingSteps: List isValidated: Boolean } class PhaseDiagramCalculator { identifyStablePhases() checkEquilibrium() } class ProcessController { manageRun() } class ThermalAnalysisRun { runAnalysis() } class ThermalCycleSimulator { coolingRate: Float peakTemperature: Float } class SafetyProtocol { emergencyStop: Boolean temperatureLimit: Float } class ResearchProject { principalInvestigator: String budget: Decimal } class ExperimentalDataset { integrityVerified: Boolean filterResults() } class SpectroscopyData { wavelength: Float emissionIntensity: Float } class MicrostructureAnalysis { correlateData() refinePhases() } class StressTestRunner { testType: String performTest() } class PerformanceMetric { load: Float incrementStep: Integer } class OptimizationResult { convergence: Float } class DesignConstraint { limitValue: Float } class RegulatoryStandard { limitValue: Float effectiveDate: Date } class ComplianceArchive { storeRecord() } class BatchRecord { primaryPhase: String qualityStatus: String } class CostEstimator { calculateExpenses() } class SupplierNetwork { findVendors() } class QualityAssurance { inspector: String isCertified: Boolean approveBatch() } class ReportGenerator { format: String compileReport() } AlloyBatch "1" *-- "0..*" MaterialSpecimen MaterialSpecimen "1" *-- "1" ElementComposition MaterialSpecimen "1" *-- "1" PhaseDistribution ExperimentPlanner ..> HeatTreatmentProfile : generates HeatTreatmentProfile ..> PhaseDiagramCalculator : validated by ProcessController "1" --> "0..*" ThermalAnalysisRun : manages ThermalAnalysisRun "1" --> "1" HeatTreatmentProfile : applies ThermalAnalysisRun ..> ThermalCycleSimulator : utilizes ThermalAnalysisRun ..> SafetyProtocol : adheres to ResearchProject "1" *-- "0..*" ExperimentalDataset ResearchProject "1" --> "0..*" DesignConstraint ExperimentalDataset "1" *-- "0..*" SpectroscopyData MicrostructureAnalysis ..> MaterialSpecimen : correlates MicrostructureAnalysis ..> SpectroscopyData : correlates MicrostructureAnalysis ..> PhaseDiagramCalculator : references StressTestRunner ..> MaterialSpecimen : tests StressTestRunner ..> PerformanceMetric : generates OptimizationResult ..> PerformanceMetric : fed by OptimizationResult --> ElementComposition : recommends ComplianceArchive "1" *-- "0..*" BatchRecord BatchRecord "0..*" --> "1" AlloyBatch BatchRecord "0..*" --> "1" RegulatoryStandard CostEstimator ..> ElementComposition : calculates from SupplierNetwork ..> DesignConstraint : meets QualityAssurance ..> AlloyBatch : approves ReportGenerator ..> PerformanceMetric : compiles ReportGenerator ..> QualityAssurance : compiles @enduml ``` # Choices Please choose from the following 3 options based on the scoring criteria: A. Response 1 is better. B. Response 2 is better. C. Tie. Please provide criterion-by-criterion scores before the final choice. Use Tie if the total scores are equal or the meaningful quality difference is small. Also, you should pay adequate and same attention to both responses. **Important**：You should act as an IMPARTIAL judge and be as OBJECTIVE as possible. AVOID ANY POSITION BIASES and ensure that the ORDER in which the responses were presented DOES NOT influence your decision. Before choosing A/B/C, first score Model 1 and Model 2 independently against each specific instruction. If the specific instruction provides a scoring scale, use that scale; otherwise use a 1-5 score where 1 means very poor alignment and 5 means excellent alignment. Base the final choice on the independent scores and the evidence, not on which model is shown first. # Output Your output should be in the following format: ```result Scores: 1. <criterion name>: Model 1 = <score>, Model 2 = <score>; Evidence: <concrete evidence from both models> 2. <criterion name>: Model 1 = <score>, Model 2 = <score>; Evidence: <concrete evidence from both models> Total: Model 1 = <total>, Model 2 = <total> Choice: A Reason: 1. Criterion name: compare Model 1 and Model 2 using concrete evidence from both models. 2. Criterion name: compare Model 1 and Model 2 using concrete evidence from both models. 3. Rejected or checked issues: mention any tempting but unsupported issue that you did not use for the decision, if relevant. 4. Overall judgment: explain why the chosen model is better, or why it is a tie. ``` | G2: codex | H2: GLM5.2 | I2: ```result Scores: 1. Design aligns with requirement (all functionalities, no hallucinations/additions): Model 1 = 4, Model 2 = 3; Evidence: Model 1 covers all required concepts: AlloyBatch, MaterialSpecimen (with grainStructure and defectAnnotation attributes per "classify grain structure, and annotate any defects"), ElementComposition, PhaseDistribution, HeatTreatmentProfile (with isValidated per "validated before use"), ProcessingStep (supported by "define processing steps"), StressTestRunner/StressTestRun (separating runner from individual test runs), ResearchProject with principalInvestigator and budget, ExperimentalDataset, SpectroscopyData, MicrostructureAnalysis, PerformanceMetric, OptimizationResult, DesignConstraint (with effectiveDate), RegulatoryStandard (with effectiveDate), ComplianceArchive, BatchRecord, CostEstimator, SupplierNetwork, QualityAssurance, ReportGenerator, SummaryReport (with ReportFormat enum). Extra classes like CostEstimation and Supplier are reasonable refinements implied by "calculating raw material expenses" and "finding vendors." Model 2 misses ProcessingStep as a separate entity (uses processingSteps: List attribute), conflates StressTestRun into StressTestRunner (no separate test-run entity), lacks SummaryReport class (format as attribute on ReportGenerator), and critically omits effectiveDate from DesignConstraint despite the requirement stating "Design Constraints and Regulatory Standards, which specify limit values and effective dates." Model 2 also lacks grainStructure and defectAnnotation on MaterialSpecimen. 2. Conceptual classes and relationships (associations, cardinalities, types: inheritance, aggregation, composition): Model 1 = 4, Model 2 = 3; Evidence: Model 1 correctly uses composition for whole-part relationships (AlloyBatch "1" *-- "1..*" MaterialSpecimen, ResearchProject "1" *-- "1..*" ExperimentalDataset, ExperimentalDataset "1" *-- "*" SpectroscopyData) and directed associations for functional relationships. It correctly attributes "utilizes simulator" and "adheres to protocols" to ProcessController (ProcessController "1" --> "1" ThermalCycleSimulator: utilizes simulator; ProcessController "1" --> "1..*" SafetyProtocol: adheres to protocols), matching the requirement that says "a Process Controller manages Thermal Analysis Runs, utilizing a Thermal Cycle Simulator...while adhering to strict Safety Protocols." PhaseDiagramCalculator is linked to both HeatTreatmentProfile (planning) and MicrostructureAnalysis (analysis reference). Model 2 incorrectly places these relationships on ThermalAnalysisRun instead of ProcessController (ThermalAnalysisRun ..> ThermalCycleSimulator : utilizes; ThermalAnalysisRun ..> SafetyProtocol : adheres to), contradicting the requirement's subject. Model 2 also extensively uses dependency relationships (..>) instead of associations for structural connections (e.g., ExperimentPlanner ..> HeatTreatmentProfile, CostEstimator ..> ElementComposition, SupplierNetwork ..> DesignConstraint), which are semantically weaker and lose structural relationship meaning. However, Model 2 does have one advantage: OptimizationResult --> ElementComposition : recommends creates a proper structural link, whereas Model 1 uses recommendedComposition: String (a weaker representation). 3. Clarity in class names and optional inclusion of attributes: Model 1 = 5, Model 2 = 3; Evidence: Model 1 uses clear, domain-aligned class names and rich attributes with six enumerations (SurfaceFinish, PhaseType, TestType, QualityStatus, RunState, ReportFormat) providing domain type-safety. All attributes map to requirement details (e.g., SafetyProtocol has maxTemperatureLimit, minTemperatureLimit, emergencyStopEnabled per "emergency stop capabilities and temperature limits"). Model 2 has clear class names but uses methods/operations (e.g., generateProfile(), manageRun(), runAnalysis()) where attributes or relationships would be more appropriate for a domain class diagram. DesignConstraint is missing effectiveDate (explicitly required). ElementComposition uses chemicalMakeup: Map and HeatTreatmentProfile uses processingSteps: List, which are implementation-flavored types. MaterialSpecimen lacks grainStructure and defectAnnotation attributes. Some classes have no domain attributes at all (e.g., ThermalAnalysisRun only has runAnalysis()). Total: Model 1 = 13, Model 2 = 9 Choice: A Reason: 1. Design alignment: Model 1 covers all required functionalities comprehensively, including ProcessingStep, StressTestRun, and SummaryReport as proper entities, and correctly includes effectiveDate on both DesignConstraint and RegulatoryStandard. Model 2 omits effectiveDate from DesignConstraint (a direct requirement violation), conflates StressTestRunner with test runs, and lacks separate ProcessingStep and SummaryReport entities. 2. Relationships and cardinalities: Model 1 correctly attributes the "utilizes" and "adheres to" relationships to ProcessController as the requirement specifies, uses appropriate relationship types (composition for containment, associations for functional links), and provides comprehensive multiplicities. Model 2 misattributes these to ThermalAnalysisRun, overuses dependency arrows (..>) instead of structural associations, and loses the compositional semantics for several key relationships. 3. Clarity and attributes: Model 1 provides rich, domain-accurate attributes and enumerations that enhance semantic clarity. Model 2 uses implementation types (Map, List), omits required attributes (effectiveDate on DesignConstraint, grainStructure and defectAnnotation on MaterialSpecimen), and substitutes methods for structural attributes in several classes. 4. Rejected or checked issues: Model 2's advantage of putting coolingRate and peakTemperature on ThermalCycleSimulator (more accurate per "a Thermal Cycle Simulator to model cooling rates and peak temperatures") and linking OptimizationResult to ElementComposition via association were considered as positive factors, but they do not compensate for the missing classes, wrong relationship attributions, and absent required attributes. Model 1's extra classes (CostEstimation, Supplier) were checked against the "no additions" criterion but found to be reasonable refinements implied by the requirement text rather than hallucinations. 5. Overall judgment: Model 1 is clearly superior due to complete requirement coverage, correct relationship attribution, proper use of UML relationship types, and comprehensive domain-accurate attributes. Model 2 has several structural inaccuracies and missing required elements that undermine its alignment with the requirement. ``` | J2: A | K2: =IF(OR(J2="",C2="",E2=""),"",IF(J2="C","D(平局)",IF(J2=IF(E2="l2r","A","B"),LEFT(C2,1),RIGHT(C2,1)))) -> A | L2: A | M2: =IF(OR(K2="",L2=""),"",--(K2=L2)) -> 1
A3: AdvancedAlloyCompositionOptimization | B3: The Advanced Alloy Composition Optimization system supports research and industrial processes for developing high-performance metal alloys. The core unit of production is an Alloy Batch, created on a specific date, which contains multiple Material Specimens. Each specimen is defined by its density and surface finish, possesses a base Element Composition describing its chemical makeup, and has a current Phase Distribution detailing the fractions of target phases such as Austenite, Ferrite, Martensite, or Pearlite. Specimens can be analyzed to determine their current phase, classify grain structure, and annotate any defects. To achieve desired material properties, the system utilizes an Experiment Planner that generates Heat Treatment Profiles. These profiles, identified by name and quenching status, define processing steps and are validated before use. The planning process relies on a Phase Diagram Calculator to identify stable phases and check for equilibrium states. During execution, a Process Controller manages Thermal Analysis Runs, utilizing a Thermal Cycle Simulator to model cooling rates and peak temperatures while adhering to strict Safety Protocols that include emergency stop capabilities and temperature limits. Each thermal analysis run applies a specific profile. Data collection is organized under Research Projects, led by a principal investigator with a defined budget and associated design constraints. Projects encompass Experimental Datasets that verify data integrity, filter results, and store generated outcomes. These datasets aggregate Spectroscopy Data, which records wavelengths and emission intensities to detect phases and analyze elemental composition. Microstructure Analysis correlates specimen samples with spectroscopic data to refine phase distributions, utilizing the Phase Diagram Calculator as a reference. Furthermore, Stress Test Runners perform destructive or non-destructive tensile tests on specimens to generate Performance Metrics regarding load and increment steps. These metrics feed into Optimization Results that track convergence and recommend optimal element compositions. The system ensures adherence to engineering and legal standards through Design Constraints and Regulatory Standards, which specify limit values and effective dates to check specimen compliance. A Compliance Archive stores Batch Records, linking regulatory standards to specific batches; each record documents the primary phase, quality status, and the associated alloy batch. Operational support includes a Cost Estimator for calculating raw material expenses based on composition, a Supplier Network for finding vendors meeting design constraints, and a Quality Assurance module where certified inspectors approve batches. Finally, a Report Generator compiles performance metrics and quality assurance sources into summary reports in various formats. | C3: A vs B | D3: faithfulness | E3: r2l | F3: You are a professional software engineer with expertise across multiple domains. You evaluate UML class diagrams from the perspective of real-world software design, applying domain knowledge and engineering best practices alongside the provided scoring criteria. Please evaluate the two diagrams (Model 1, Model 2) based on the provided requirement and scoring criteria. # Criteria **CRITICAL INSTRUCTION**: You MUST evaluate the responses against EACH AND EVERY criterion listed in the "Specific Instructions" one by one. DO NOT aggregate, summarize, or skip any criterion. **Specific Instructions**: - Ensure that the design aligns with the given requirement strictly, achieving all the functionalities based on the requirements without making any hallucinations and additions. Ensure that the conceptual classes and their relationships accurately represent the essentials outlined in the requirement. This includes a detailed focus on the associations between classes, their cardinalities, and the types of relationships such as inheritance, aggregation, and composition. Clarity in class names and the optional inclusion of attributes are key for aligning with the project's vision. # Evaluation Guidelines ## General Rules - Consider only UML class diagram semantics (e.g., classes, attributes, associations, multiplicities, generalisation, composition/aggregation). - Ignore layout, styling, skinparams, comments, and notes. - If the response is incomplete or misses any required key component, regard it as a bad one. - Give credit for semantic clarity, but not for layout, comments, visibility markers, or other presentation-only differences. ## Forbidden Penalties (Strictly Enforced) You MUST NOT deduct points, lower scores, or claim a model is "worse", "complex", or "less practical" based on ANY of the following: 1. **Association Styles**: Using two opposite unidirectional associations (e.g., `A --> B` and `B --> A`) instead of one single bidirectional line (e.g., `A -- B`). They are 100% semantically equivalent. Treat opposite-direction associations as equivalent unless role labels, multiplicities, or navigability contradict the requirements. 2. **PlantUML Comments**: Using single-quote comments (e.g., `'opposite bank`) at the end of lines. These are standard tooling annotations — ignore them for scoring unless they obscure or contradict the relation meaning. 3. **Primitive Types**: Using common aliases for types (e.g., `int` instead of `Integer`, `str` instead of `String`, `boolean` instead of `Boolean`). Lowercase or language-flavored spellings are acceptable. 4. **Equivalent Multiplicity Literals**: Using `*` instead of `0..*`, or `1` instead of `1..1`. These pairs are semantically identical. 5. **Optional Abstractness**: Marking or not marking a superclass as `abstract` when the requirement does not say whether direct instances are allowed. Do not reward either style without requirement evidence. These forbidden factors must not appear as negative evidence under any criterion and must not affect criterion scores or the final choice. ## Evidence & Calibration Requirements - For every criterion you discuss, cite concrete evidence from both models. Quote or closely paraphrase the relevant class, attribute, association, multiplicity, inheritance, note, or missing element. - Do not claim a class, attribute, or association is missing when a synonymous or directly related element is present. If the present element is indirect, vague, over-constrained, or semantically weak, state that precise weakness instead. - Distinguish omissions from contradictions. Missing a hard constraint is usually less severe than explicitly modeling the opposite or an invalid multiplicity. - Do not reward a simpler model merely for being shorter if the more detailed model uses traceable intermediate workflow/concept classes required for domain reasoning. - Do not penalize a detailed model merely for using transparent refinements such as `Definition`, `Placement`, `Entry`, `Session`, `State`, `Record`, `Assignment`, `Arrangement`, or `Need` when the base requirement term remains recognizable. - Do not reward extra identifiers, timestamps, statuses, classes, or implementation-oriented detail unless they improve coverage of a stated requirement fact. - Text introduced by `e.g.`, `for example`, or `such as` gives examples, not a complete enumeration, unless the requirement explicitly declares a closed list. - Keep UML/PlantUML standards separate from domain accuracy. Domain-faithfulness problems, wrong business multiplicities, missing constraints, or vague semantics belong under the domain criteria, not UML standards, unless they make the notation invalid or unreadable. - When evaluating position bias, remember that Model 1 and Model 2 may be swapped in a second pass. Use only the content under each model block, not assumptions from prior comparisons or labels. # Requirement ``` The Advanced Alloy Composition Optimization system supports research and industrial processes for developing high-performance metal alloys. The core unit of production is an Alloy Batch, created on a specific date, which contains multiple Material Specimens. Each specimen is defined by its density and surface finish, possesses a base Element Composition describing its chemical makeup, and has a current Phase Distribution detailing the fractions of target phases such as Austenite, Ferrite, Martensite, or Pearlite. Specimens can be analyzed to determine their current phase, classify grain structure, and annotate any defects. To achieve desired material properties, the system utilizes an Experiment Planner that generates Heat Treatment Profiles. These profiles, identified by name and quenching status, define processing steps and are validated before use. The planning process relies on a Phase Diagram Calculator to identify stable phases and check for equilibrium states. During execution, a Process Controller manages Thermal Analysis Runs, utilizing a Thermal Cycle Simulator to model cooling rates and peak temperatures while adhering to strict Safety Protocols that include emergency stop capabilities and temperature limits. Each thermal analysis run applies a specific profile. Data collection is organized under Research Projects, led by a principal investigator with a defined budget and associated design constraints. Projects encompass Experimental Datasets that verify data integrity, filter results, and store generated outcomes. These datasets aggregate Spectroscopy Data, which records wavelengths and emission intensities to detect phases and analyze elemental composition. Microstructure Analysis correlates specimen samples with spectroscopic data to refine phase distributions, utilizing the Phase Diagram Calculator as a reference. Furthermore, Stress Test Runners perform destructive or non-destructive tensile tests on specimens to generate Performance Metrics regarding load and increment steps. These metrics feed into Optimization Results that track convergence and recommend optimal element compositions. The system ensures adherence to engineering and legal standards through Design Constraints and Regulatory Standards, which specify limit values and effective dates to check specimen compliance. A Compliance Archive stores Batch Records, linking regulatory standards to specific batches; each record documents the primary phase, quality status, and the associated alloy batch. Operational support includes a Cost Estimator for calculating raw material expenses based on composition, a Supplier Network for finding vendors meeting design constraints, and a Quality Assurance module where certified inspectors approve batches. Finally, a Report Generator compiles performance metrics and quality assurance sources into summary reports in various formats. ``` # Model 1 ``` @startuml skinparam classAttributeIconSize 0 hide empty members class AlloyBatch { creationDate: Date } class MaterialSpecimen { density: Float surfaceFinish: String } class ElementComposition { chemicalMakeup: Map } class PhaseDistribution { austenite: Float ferrite: Float martensite: Float pearlite: Float } class ExperimentPlanner { generateProfile() } class HeatTreatmentProfile { name: String quenchingStatus: Boolean processingSteps: List isValidated: Boolean } class PhaseDiagramCalculator { identifyStablePhases() checkEquilibrium() } class ProcessController { manageRun() } class ThermalAnalysisRun { runAnalysis() } class ThermalCycleSimulator { coolingRate: Float peakTemperature: Float } class SafetyProtocol { emergencyStop: Boolean temperatureLimit: Float } class ResearchProject { principalInvestigator: String budget: Decimal } class ExperimentalDataset { integrityVerified: Boolean filterResults() } class SpectroscopyData { wavelength: Float emissionIntensity: Float } class MicrostructureAnalysis { correlateData() refinePhases() } class StressTestRunner { testType: String performTest() } class PerformanceMetric { load: Float incrementStep: Integer } class OptimizationResult { convergence: Float } class DesignConstraint { limitValue: Float } class RegulatoryStandard { limitValue: Float effectiveDate: Date } class ComplianceArchive { storeRecord() } class BatchRecord { primaryPhase: String qualityStatus: String } class CostEstimator { calculateExpenses() } class SupplierNetwork { findVendors() } class QualityAssurance { inspector: String isCertified: Boolean approveBatch() } class ReportGenerator { format: String compileReport() } AlloyBatch "1" *-- "0..*" MaterialSpecimen MaterialSpecimen "1" *-- "1" ElementComposition MaterialSpecimen "1" *-- "1" PhaseDistribution ExperimentPlanner ..> HeatTreatmentProfile : generates HeatTreatmentProfile ..> PhaseDiagramCalculator : validated by ProcessController "1" --> "0..*" ThermalAnalysisRun : manages ThermalAnalysisRun "1" --> "1" HeatTreatmentProfile : applies ThermalAnalysisRun ..> ThermalCycleSimulator : utilizes ThermalAnalysisRun ..> SafetyProtocol : adheres to ResearchProject "1" *-- "0..*" ExperimentalDataset ResearchProject "1" --> "0..*" DesignConstraint ExperimentalDataset "1" *-- "0..*" SpectroscopyData MicrostructureAnalysis ..> MaterialSpecimen : correlates MicrostructureAnalysis ..> SpectroscopyData : correlates MicrostructureAnalysis ..> PhaseDiagramCalculator : references StressTestRunner ..> MaterialSpecimen : tests StressTestRunner ..> PerformanceMetric : generates OptimizationResult ..> PerformanceMetric : fed by OptimizationResult --> ElementComposition : recommends ComplianceArchive "1" *-- "0..*" BatchRecord BatchRecord "0..*" --> "1" AlloyBatch BatchRecord "0..*" --> "1" RegulatoryStandard CostEstimator ..> ElementComposition : calculates from SupplierNetwork ..> DesignConstraint : meets QualityAssurance ..> AlloyBatch : approves ReportGenerator ..> PerformanceMetric : compiles ReportGenerator ..> QualityAssurance : compiles @enduml ``` # Model 2 ``` @startuml ' Enumerations enum SurfaceFinish { POLISHED ROUGH MACHINED AS_CAST } enum PhaseType { AUSTENITE FERRITE MARTENSITE PEARLITE } enum TestType { DESTRUCTIVE NON_DESTRUCTIVE } enum QualityStatus { APPROVED REJECTED PENDING } enum RunState { INITIALIZED HEATING HOLDING COOLING COMPLETED EMERGENCY_STOP } enum ReportFormat { PDF CSV JSON HTML } ' Domain Classes class AlloyBatch { batchId: String creationDate: Date name: String } class MaterialSpecimen { specimenId: String density: double surfaceFinish: SurfaceFinish grainStructure: String defectAnnotation: String } class ElementComposition { elementName: String percentage: double } class PhaseDistribution { phaseType: PhaseType fraction: double } class ExperimentPlanner { plannerId: String name: String } class HeatTreatmentProfile { profileId: String name: String quenchingStatus: boolean isValidated: boolean } class ProcessingStep { stepOrder: int targetTemperature: double durationMinutes: int description: String } class PhaseDiagramCalculator { calculatorId: String name: String equilibriumState: boolean stablePhases: String } class ProcessController { controllerId: String name: String } class ThermalAnalysisRun { runId: String currentState: RunState peakTemperature: double coolingRate: double startTime: Date endTime: Date } class ThermalCycleSimulator { simulatorId: String name: String } class SafetyProtocol { protocolId: String maxTemperatureLimit: double minTemperatureLimit: double emergencyStopEnabled: boolean } class ResearchProject { projectId: String projectName: String principalInvestigator: String budget: double } class ExperimentalDataset { datasetId: String name: String dataIntegrityVerified: boolean creationDate: Date filterCriteria: String resultsFiltered: boolean } class SpectroscopyData { dataId: String wavelength: double emissionIntensity: double detectedPhase: PhaseType timestamp: Date } class MicrostructureAnalysis { analysisId: String correlatedPhase: PhaseType refinedFraction: double description: String } class StressTestRunner { runnerId: String name: String } class StressTestRun { testId: String testType: TestType maxLoad: double incrementStep: double timestamp: Date } class PerformanceMetric { metricId: String loadValue: double incrementValue: double stressValue: double strainValue: double } class OptimizationResult { resultId: String convergenceTracked: boolean iterationCount: int recommendedComposition: String } class DesignConstraint { constraintId: String constraintName: String limitValue: double effectiveDate: Date } class RegulatoryStandard { standardId: String standardName: String limitValue: double effectiveDate: Date } class ComplianceArchive { archiveId: String archiveDate: Date } class BatchRecord { recordId: String primaryPhase: PhaseType qualityStatus: QualityStatus recordDate: Date } class CostEstimator { estimatorId: String name: String } class CostEstimation { estimationId: String totalCost: double currency: String calculationDate: Date } class SupplierNetwork { networkId: String name: String } class Supplier { supplierId: String name: String meetsConstraints: boolean contactInfo: String } class QualityAssurance { moduleId: String name: String } class QualityAssuranceReview { reviewId: String inspectorName: String inspectorCertified: boolean approvalDate: Date isApproved: boolean } class ReportGenerator { generatorId: String name: String } class SummaryReport { reportId: String title: String format: ReportFormat generationDate: Date } ' Associations and Compositions AlloyBatch "1" *-- "1..*" MaterialSpecimen: contains specimens MaterialSpecimen "1" *-- "1..*" ElementComposition: base composition MaterialSpecimen "1" *-- "1..*" PhaseDistribution: current phases ExperimentPlanner "1" --> "1..*" HeatTreatmentProfile: generates profiles HeatTreatmentProfile "1" *-- "1..*" ProcessingStep: defined steps PhaseDiagramCalculator "1" --> "*" HeatTreatmentProfile: references for planning PhaseDiagramCalculator "1" --> "*" MicrostructureAnalysis: references for analysis ProcessController "1" --> "1..*" ThermalAnalysisRun: manages runs ProcessController "1" --> "1" ThermalCycleSimulator: utilizes simulator ProcessController "1" --> "1..*" SafetyProtocol: adheres to protocols ThermalCycleSimulator "1" --> "*" ThermalAnalysisRun: simulates ThermalAnalysisRun "*" --> "1" HeatTreatmentProfile: applies profile ResearchProject "1" *-- "1..*" ExperimentalDataset: encompassed datasets ResearchProject "1" --> "1..*" DesignConstraint: associated constraints ExperimentalDataset "1" *-- "*" SpectroscopyData: aggregated data ExperimentalDataset "1" *-- "*" MicrostructureAnalysis: included analyses MicrostructureAnalysis "*" --> "1" MaterialSpecimen: correlates specimen MicrostructureAnalysis "*" --> "1" SpectroscopyData: correlates spectroscopic data StressTestRunner "1" --> "1..*" StressTestRun: performs tests MaterialSpecimen "1" --> "*" StressTestRun: tested in StressTestRun "1" *-- "1..*" PerformanceMetric: generated metrics PerformanceMetric "*" --> "1" OptimizationResult: feeds into ComplianceArchive "1" *-- "1..*" BatchRecord: stored records BatchRecord "*" --> "1" AlloyBatch: documents batch BatchRecord "*" --> "1..*" RegulatoryStandard: linked standards CostEstimator "1" --> "*" AlloyBatch: estimates costs for CostEstimator "1" --> "*" ElementComposition: calculates based on CostEstimator "1" --> "*" CostEstimation: produces estimations AlloyBatch "1" --> "1" CostEstimation: estimated by SupplierNetwork "1" --> "*" Supplier: finds vendors SupplierNetwork "1" --> "*" DesignConstraint: matches constraints QualityAssurance "1" --> "*" QualityAssuranceReview: conducts reviews AlloyBatch "1" --> "*" QualityAssuranceReview: reviewed in ReportGenerator "1" --> "*" SummaryReport: compiles reports ReportGenerator "*" --> "*" PerformanceMetric: compiles from metrics ReportGenerator "*" --> "*" QualityAssuranceReview: compiles from reviews @enduml ``` # Choices Please choose from the following 3 options based on the scoring criteria: A. Response 1 is better. B. Response 2 is better. C. Tie. Please provide criterion-by-criterion scores before the final choice. Use Tie if the total scores are equal or the meaningful quality difference is small. Also, you should pay adequate and same attention to both responses. **Important**：You should act as an IMPARTIAL judge and be as OBJECTIVE as possible. AVOID ANY POSITION BIASES and ensure that the ORDER in which the responses were presented DOES NOT influence your decision. Before choosing A/B/C, first score Model 1 and Model 2 independently against each specific instruction. If the specific instruction provides a scoring scale, use that scale; otherwise use a 1-5 score where 1 means very poor alignment and 5 means excellent alignment. Base the final choice on the independent scores and the evidence, not on which model is shown first. # Output Your output should be in the following format: ```result Scores: 1. <criterion name>: Model 1 = <score>, Model 2 = <score>; Evidence: <concrete evidence from both models> 2. <criterion name>: Model 1 = <score>, Model 2 = <score>; Evidence: <concrete evidence from both models> Total: Model 1 = <total>, Model 2 = <total> Choice: A Reason: 1. Criterion name: compare Model 1 and Model 2 using concrete evidence from both models. 2. Criterion name: compare Model 1 and Model 2 using concrete evidence from both models. 3. Rejected or checked issues: mention any tempting but unsupported issue that you did not use for the decision, if relevant. 4. Overall judgment: explain why the chosen model is better, or why it is a tie. ``` | G3: codex | H3: GLM5.2 | I3: Based on my thorough trace of every requirement element against both models, I now have enough evidence to evaluate criterion-by-criterion. ```result Scores: 1. Strict requirement alignment (all functionalities, no hallucinations): Model 1 = 2.5, Model 2 = 3.5; Evidence: M1 omits `grainStructure` and `defectAnnotation` from MaterialSpecimen (requirement: "classify grain structure, and annotate any defects"), omits `effectiveDate` from DesignConstraint (requirement: "specify limit values and effective dates"), and omits `detectedPhase` from SpectroscopyData (requirement: "detect phases"). M2 includes all of these (`grainStructure`, `defectAnnotation`, `detectedPhase`, `effectiveDate` on DesignConstraint). However, M2 misplaces `coolingRate`/`peakTemperature` onto `ThermalAnalysisRun` rather than `ThermalCycleSimulator` (requirement: "utilizing a Thermal Cycle Simulator to model cooling rates and peak temperatures"), and loses the `OptimizationResult → ElementComposition` recommendation link (only `recommendedComposition: String`). M1 correctly places simulator attributes and the recommends-link. M2's extra classes (ProcessingStep, StressTestRun, CostEstimation, Supplier, SummaryReport) are transparent refinements mapping to requirement facts, not hallucinations. 2. Conceptual classes and relationships accurately represent essentials: Model 1 = 3, Model 2 = 3.5; Evidence: Both contain all core classes. M1 models most cross-cutting links as dependencies (`..>`) without cardinality (e.g., `ExperimentPlanner ..> HeatTreatmentProfile`, `MicrostructureAnalysis ..> PhaseDiagramCalculator`, `CostEstimator ..> ElementComposition`), which weakens structural representation. M2 uses proper associations with cardinalities throughout and adds recognizable refinement classes (Supplier↔"vendors", SummaryReport↔"summary reports", ProcessingStep↔"processing steps"). M2 reverses the `MicrostructureAnalysis → PhaseDiagramCalculator` direction (`PhaseDiagramCalculator "1" --> "*" MicrostructureAnalysis` vs. requirement "utilizing the Phase Diagram Calculator as a reference"), and reverses `PhaseDiagramCalculator → HeatTreatmentProfile`; M1 has the correct direction for the MicrostructureAnalysis reference. 3. Associations, cardinalities, and relationship types: Model 1 = 2.5, Model 2 = 3.5; Evidence: M1 uses composition correctly for part-whole links (`AlloyBatch *-- MaterialSpecimen`, `ResearchProject *-- ExperimentalDataset`, `ComplianceArchive *-- BatchRecord`). But `ThermalAnalysisRun "1" --> "1" HeatTreatmentProfile` is too restrictive (a profile can be applied by multiple runs; M2's `"*" --> "1"` is correct), `BatchRecord "0..*" --> "1" RegulatoryStandard` allows only one standard (requirement: "linking regulatory standards", plural; M2's `"*" --> "1..*"` is correct), and M1 attributes "utilizes simulator"/"adheres to protocols" to `ThermalAnalysisRun` rather than `ProcessController` (requirement subject is ProcessController). M2 correctly attributes all three to `ProcessController` and has correct multiplicities for profile and standards, though M2's reversed MicrostructureAnalysis navigability is one error. M1's `AlloyBatch "1" *-- "0..*"` allows zero specimens vs. requirement "contains multiple". 4. Clarity in class names and optional attributes: Model 1 = 3.5, Model 2 = 4; Evidence: Both use clear, requirement-matching class names. M2 adds typed enums (`TestType{DESTRUCTIVE,NON_DESTRUCTIVE}`, `QualityStatus`, `PhaseType`, `ReportFormat`) that directly map to requirement facts ("destructive or non-destructive", "quality status", "various formats"), improving semantic clarity. M1 uses `testType: String` and `format: String` (acceptable but less precise). M1 hardcodes the four phase fractions as named attributes (`austenite`, `ferrite`, `martensite`, `pearlite`) which slightly over-constrains the "such as" non-closed list; M2's `phaseType` enum + `fraction` is more faithful. Total: Model 1 = 11.5, Model 2 = 14.5 Choice: B Reason: 1. Strict requirement alignment: M2 covers more requirement attributes (grainStructure, defectAnnotation, detectedPhase, DesignConstraint.effectiveDate) that M1 omits entirely. M2's extra classes are transparent refinements tied to requirement facts (Supplier↔"vendors", SummaryReport↔"summary reports", ProcessingStep↔"processing steps"), not hallucinations. M1 does better on three specific points (simulator attribute placement, MicrostructureAnalysis→Calculator direction, OptimizationResult→ElementComposition recommends link), but these are outweighed by its larger set of omissions. 2. Associations and cardinalities: M2 is clearly stronger — correct `ThermalAnalysisRun "*" --> "1" HeatTreatmentProfile`, correct `BatchRecord "*" --> "1..*" RegulatoryStandard` (plural standards), and correct ProcessController attribution for simulator/protocols. M1 has the restrictive `1..1` profile multiplicity, single-standard BatchRecord, and misattributed simulator/protocol links, plus relies heavily on uncardinalized dependencies. 3. Rejected or checked issues: I did not penalize M2 for implementation-oriented ids/timestamps (per guidelines, not rewarded but not penalized). I did not penalize M1 for using `Float`/`int` or `*` literals. I did not reward M2 merely for being longer — its additional classes were credited only where they map to stated requirement facts. M1's hardcoded four phase attributes were noted as slightly over-constrained by the "such as" phrasing but not heavily penalized. M2's reversed PhaseDiagramCalculator directions (to both HeatTreatmentProfile and MicrostructureAnalysis) were counted as domain/navigability errors, reducing its criterion-2/3 scores but not enough to override its coverage advantage. 4. Overall judgment: M2 is better. It achieves broader functional coverage of the requirement, uses proper associations with correct cardinalities, correctly attributes ProcessController's three responsibilities, and models standards/batch-record multiplicities faithfully. M1 is more compact but omits several stated attributes, uses dependency arrows without cardinality for most structural relationships, and has multiple multiplicity/attribution errors. M2's three directional/placement errors are real but fewer and less pervasive than M1's combined omissions and cardinality mistakes. ``` | J3: B | K3: =IF(OR(J3="",C3="",E3=""),"",IF(J3="C","D(平局)",IF(J3=IF(E3="l2r","A","B"),LEFT(C3,1),RIGHT(C3,1)))) -> A | L3: A | M3: =IF(OR(K3="",L3=""),"",--(K3=L3)) -> 1
