Workbook

Sheet 实验结果
A1: 需求name | B1: 需求描述 | C1: 类别 | D1: 指标类别 | E1: 位置 | F1: 提示词 | G1: 生产模式设置 | H1: 基座模型设置 | I1: 输出结果 | J1: 最终结果 | K1: 实际结果 | L1: 人工打标 | M1: 一致性
A2: AdvancedAlloyCompositionOptimization | B2: The Advanced Alloy Composition Optimization system supports research and industrial processes for developing high-performance metal alloys. The core unit of production is an Alloy Batch, created on a specific date, which contains multiple Material Specimens. Each specimen is defined by its density and surface finish, possesses a base Element Composition describing its chemical makeup, and has a current Phase Distribution detailing the fractions of target phases such as Austenite, Ferrite, Martensite, or Pearlite. Specimens can be analyzed to determine their current phase, classify grain structure, and annotate any defects. To achieve desired material properties, the system utilizes an Experiment Planner that generates Heat Treatment Profiles. These profiles, identified by name and quenching status, define processing steps and are validated before use. The planning process relies on a Phase Diagram Calculator to identify stable phases and check for equilibrium states. During execution, a Process Controller manages Thermal Analysis Runs, utilizing a Thermal Cycle Simulator to model cooling rates and peak temperatures while adhering to strict Safety Protocols that include emergency stop capabilities and temperature limits. Each thermal analysis run applies a specific profile. Data collection is organized under Research Projects, led by a principal investigator with a defined budget and associated design constraints. Projects encompass Experimental Datasets that verify data integrity, filter results, and store generated outcomes. These datasets aggregate Spectroscopy Data, which records wavelengths and emission intensities to detect phases and analyze elemental composition. Microstructure Analysis correlates specimen samples with spectroscopic data to refine phase distributions, utilizing the Phase Diagram Calculator as a reference. Furthermore, Stress Test Runners perform destructive or non-destructive tensile tests on specimens to generate Performance Metrics regarding load and increment steps. These metrics feed into Optimization Results that track convergence and recommend optimal element compositions. The system ensures adherence to engineering and legal standards through Design Constraints and Regulatory Standards, which specify limit values and effective dates to check specimen compliance. A Compliance Archive stores Batch Records, linking regulatory standards to specific batches; each record documents the primary phase, quality status, and the associated alloy batch. Operational support includes a Cost Estimator for calculating raw material expenses based on composition, a Supplier Network for finding vendors meeting design constraints, and a Quality Assurance module where certified inspectors approve batches. Finally, a Report Generator compiles performance metrics and quality assurance sources into summary reports in various formats. | C2: A vs B | D2: faithfulness | E2: l2r | F2: You are a professional software engineer with expertise across multiple domains. You evaluate UML class diagrams from the perspective of real-world software design, applying domain knowledge and engineering best practices alongside the provided scoring criteria. Please evaluate the two diagrams (Model 1, Model 2) based on the provided requirement and scoring criteria. # Criteria **CRITICAL INSTRUCTION**: You MUST evaluate the responses against EACH AND EVERY criterion listed in the "Specific Instructions" one by one. DO NOT aggregate, summarize, or skip any criterion. **Specific Instructions**: - Ensure that the design aligns with the given requirement strictly, achieving all the functionalities based on the requirements without making any hallucinations and additions. Ensure that the conceptual classes and their relationships accurately represent the essentials outlined in the requirement. This includes a detailed focus on the associations between classes, their cardinalities, and the types of relationships such as inheritance, aggregation, and composition. Clarity in class names and the optional inclusion of attributes are key for aligning with the project's vision. # Evaluation Guidelines ## General Rules - Consider only UML class diagram semantics (e.g., classes, attributes, associations, multiplicities, generalisation, composition/aggregation). - Ignore layout, styling, skinparams, comments, and notes. - If the response is incomplete or misses any required key component, regard it as a bad one. - Give credit for semantic clarity, but not for layout, comments, visibility markers, or other presentation-only differences. ## Forbidden Penalties (Strictly Enforced) You MUST NOT deduct points, lower scores, or claim a model is "worse", "complex", or "less practical" based on ANY of the following: 1. **Association Styles**: Using two opposite unidirectional associations (e.g., `A --> B` and `B --> A`) instead of one single bidirectional line (e.g., `A -- B`). They are 100% semantically equivalent. Treat opposite-direction associations as equivalent unless role labels, multiplicities, or navigability contradict the requirements. 2. **PlantUML Comments**: Using single-quote comments (e.g., `'opposite bank`) at the end of lines. These are standard tooling annotations — ignore them for scoring unless they obscure or contradict the relation meaning. 3. **Primitive Types**: Using common aliases for types (e.g., `int` instead of `Integer`, `str` instead of `String`, `boolean` instead of `Boolean`). Lowercase or language-flavored spellings are acceptable. 4. **Equivalent Multiplicity Literals**: Using `*` instead of `0..*`, or `1` instead of `1..1`. These pairs are semantically identical. 5. **Optional Abstractness**: Marking or not marking a superclass as `abstract` when the requirement does not say whether direct instances are allowed. Do not reward either style without requirement evidence. These forbidden factors must not appear as negative evidence under any criterion and must not affect criterion scores or the final choice. ## Evidence & Calibration Requirements - For every criterion you discuss, cite concrete evidence from both models. Quote or closely paraphrase the relevant class, attribute, association, multiplicity, inheritance, note, or missing element. - Do not claim a class, attribute, or association is missing when a synonymous or directly related element is present. If the present element is indirect, vague, over-constrained, or semantically weak, state that precise weakness instead. - Distinguish omissions from contradictions. Missing a hard constraint is usually less severe than explicitly modeling the opposite or an invalid multiplicity. - Do not reward a simpler model merely for being shorter if the more detailed model uses traceable intermediate workflow/concept classes required for domain reasoning. - Do not penalize a detailed model merely for using transparent refinements such as `Definition`, `Placement`, `Entry`, `Session`, `State`, `Record`, `Assignment`, `Arrangement`, or `Need` when the base requirement term remains recognizable. - Do not reward extra identifiers, timestamps, statuses, classes, or implementation-oriented detail unless they improve coverage of a stated requirement fact. - Text introduced by `e.g.`, `for example`, or `such as` gives examples, not a complete enumeration, unless the requirement explicitly declares a closed list. - Keep UML/PlantUML standards separate from domain accuracy. Domain-faithfulness problems, wrong business multiplicities, missing constraints, or vague semantics belong under the domain criteria, not UML standards, unless they make the notation invalid or unreadable. - When evaluating position bias, remember that Model 1 and Model 2 may be swapped in a second pass. Use only the content under each model block, not assumptions from prior comparisons or labels. # Requirement ``` The Advanced Alloy Composition Optimization system supports research and industrial processes for developing high-performance metal alloys. The core unit of production is an Alloy Batch, created on a specific date, which contains multiple Material Specimens. Each specimen is defined by its density and surface finish, possesses a base Element Composition describing its chemical makeup, and has a current Phase Distribution detailing the fractions of target phases such as Austenite, Ferrite, Martensite, or Pearlite. Specimens can be analyzed to determine their current phase, classify grain structure, and annotate any defects. To achieve desired material properties, the system utilizes an Experiment Planner that generates Heat Treatment Profiles. These profiles, identified by name and quenching status, define processing steps and are validated before use. The planning process relies on a Phase Diagram Calculator to identify stable phases and check for equilibrium states. During execution, a Process Controller manages Thermal Analysis Runs, utilizing a Thermal Cycle Simulator to model cooling rates and peak temperatures while adhering to strict Safety Protocols that include emergency stop capabilities and temperature limits. Each thermal analysis run applies a specific profile. Data collection is organized under Research Projects, led by a principal investigator with a defined budget and associated design constraints. Projects encompass Experimental Datasets that verify data integrity, filter results, and store generated outcomes. These datasets aggregate Spectroscopy Data, which records wavelengths and emission intensities to detect phases and analyze elemental composition. Microstructure Analysis correlates specimen samples with spectroscopic data to refine phase distributions, utilizing the Phase Diagram Calculator as a reference. Furthermore, Stress Test Runners perform destructive or non-destructive tensile tests on specimens to generate Performance Metrics regarding load and increment steps. These metrics feed into Optimization Results that track convergence and recommend optimal element compositions. The system ensures adherence to engineering and legal standards through Design Constraints and Regulatory Standards, which specify limit values and effective dates to check specimen compliance. A Compliance Archive stores Batch Records, linking regulatory standards to specific batches; each record documents the primary phase, quality status, and the associated alloy batch. Operational support includes a Cost Estimator for calculating raw material expenses based on composition, a Supplier Network for finding vendors meeting design constraints, and a Quality Assurance module where certified inspectors approve batches. Finally, a Report Generator compiles performance metrics and quality assurance sources into summary reports in various formats. ``` # Model 1 ``` @startuml ' Enumerations enum SurfaceFinish { POLISHED ROUGH MACHINED AS_CAST } enum PhaseType { AUSTENITE FERRITE MARTENSITE PEARLITE } enum TestType { DESTRUCTIVE NON_DESTRUCTIVE } enum QualityStatus { APPROVED REJECTED PENDING } enum RunState { INITIALIZED HEATING HOLDING COOLING COMPLETED EMERGENCY_STOP } enum ReportFormat { PDF CSV JSON HTML } ' Domain Classes class AlloyBatch { batchId: String creationDate: Date name: String } class MaterialSpecimen { specimenId: String density: double surfaceFinish: SurfaceFinish grainStructure: String defectAnnotation: String } class ElementComposition { elementName: String percentage: double } class PhaseDistribution { phaseType: PhaseType fraction: double } class ExperimentPlanner { plannerId: String name: String } class HeatTreatmentProfile { profileId: String name: String quenchingStatus: boolean isValidated: boolean } class ProcessingStep { stepOrder: int targetTemperature: double durationMinutes: int description: String } class PhaseDiagramCalculator { calculatorId: String name: String equilibriumState: boolean stablePhases: String } class ProcessController { controllerId: String name: String } class ThermalAnalysisRun { runId: String currentState: RunState peakTemperature: double coolingRate: double startTime: Date endTime: Date } class ThermalCycleSimulator { simulatorId: String name: String } class SafetyProtocol { protocolId: String maxTemperatureLimit: double minTemperatureLimit: double emergencyStopEnabled: boolean } class ResearchProject { projectId: String projectName: String principalInvestigator: String budget: double } class ExperimentalDataset { datasetId: String name: String dataIntegrityVerified: boolean creationDate: Date filterCriteria: String resultsFiltered: boolean } class SpectroscopyData { dataId: String wavelength: double emissionIntensity: double detectedPhase: PhaseType timestamp: Date } class MicrostructureAnalysis { analysisId: String correlatedPhase: PhaseType refinedFraction: double description: String } class StressTestRunner { runnerId: String name: String } class StressTestRun { testId: String testType: TestType maxLoad: double incrementStep: double timestamp: Date } class PerformanceMetric { metricId: String loadValue: double incrementValue: double stressValue: double strainValue: double } class OptimizationResult { resultId: String convergenceTracked: boolean iterationCount: int recommendedComposition: String } class DesignConstraint { constraintId: String constraintName: String limitValue: double effectiveDate: Date } class RegulatoryStandard { standardId: String standardName: String limitValue: double effectiveDate: Date } class ComplianceArchive { archiveId: String archiveDate: Date } class BatchRecord { recordId: String primaryPhase: PhaseType qualityStatus: QualityStatus recordDate: Date } class CostEstimator { estimatorId: String name: String } class CostEstimation { estimationId: String totalCost: double currency: String calculationDate: Date } class SupplierNetwork { networkId: String name: String } class Supplier { supplierId: String name: String meetsConstraints: boolean contactInfo: String } class QualityAssurance { moduleId: String name: String } class QualityAssuranceReview { reviewId: String inspectorName: String inspectorCertified: boolean approvalDate: Date isApproved: boolean } class ReportGenerator { generatorId: String name: String } class SummaryReport { reportId: String title: String format: ReportFormat generationDate: Date } ' Associations and Compositions AlloyBatch "1" *-- "1..*" MaterialSpecimen: contains specimens MaterialSpecimen "1" *-- "1..*" ElementComposition: base composition MaterialSpecimen "1" *-- "1..*" PhaseDistribution: current phases ExperimentPlanner "1" --> "1..*" HeatTreatmentProfile: generates profiles HeatTreatmentProfile "1" *-- "1..*" ProcessingStep: defined steps PhaseDiagramCalculator "1" --> "*" HeatTreatmentProfile: references for planning PhaseDiagramCalculator "1" --> "*" MicrostructureAnalysis: references for analysis ProcessController "1" --> "1..*" ThermalAnalysisRun: manages runs ProcessController "1" --> "1" ThermalCycleSimulator: utilizes simulator ProcessController "1" --> "1..*" SafetyProtocol: adheres to protocols ThermalCycleSimulator "1" --> "*" ThermalAnalysisRun: simulates ThermalAnalysisRun "*" --> "1" HeatTreatmentProfile: applies profile ResearchProject "1" *-- "1..*" ExperimentalDataset: encompassed datasets ResearchProject "1" --> "1..*" DesignConstraint: associated constraints ExperimentalDataset "1" *-- "*" SpectroscopyData: aggregated data ExperimentalDataset "1" *-- "*" MicrostructureAnalysis: included analyses MicrostructureAnalysis "*" --> "1" MaterialSpecimen: correlates specimen MicrostructureAnalysis "*" --> "1" SpectroscopyData: correlates spectroscopic data StressTestRunner "1" --> "1..*" StressTestRun: performs tests MaterialSpecimen "1" --> "*" StressTestRun: tested in StressTestRun "1" *-- "1..*" PerformanceMetric: generated metrics PerformanceMetric "*" --> "1" OptimizationResult: feeds into ComplianceArchive "1" *-- "1..*" BatchRecord: stored records BatchRecord "*" --> "1" AlloyBatch: documents batch BatchRecord "*" --> "1..*" RegulatoryStandard: linked standards CostEstimator "1" --> "*" AlloyBatch: estimates costs for CostEstimator "1" --> "*" ElementComposition: calculates based on CostEstimator "1" --> "*" CostEstimation: produces estimations AlloyBatch "1" --> "1" CostEstimation: estimated by SupplierNetwork "1" --> "*" Supplier: finds vendors SupplierNetwork "1" --> "*" DesignConstraint: matches constraints QualityAssurance "1" --> "*" QualityAssuranceReview: conducts reviews AlloyBatch "1" --> "*" QualityAssuranceReview: reviewed in ReportGenerator "1" --> "*" SummaryReport: compiles reports ReportGenerator "*" --> "*" PerformanceMetric: compiles from metrics ReportGenerator "*" --> "*" QualityAssuranceReview: compiles from reviews @enduml ``` # Model 2 ``` @startuml skinparam classAttributeIconSize 0 hide empty members class AlloyBatch { creationDate: Date } class MaterialSpecimen { density: Float surfaceFinish: String } class ElementComposition { chemicalMakeup: Map } class PhaseDistribution { austenite: Float ferrite: Float martensite: Float pearlite: Float } class ExperimentPlanner { generateProfile() } class HeatTreatmentProfile { name: String quenchingStatus: Boolean processingSteps: List isValidated: Boolean } class PhaseDiagramCalculator { identifyStablePhases() checkEquilibrium() } class ProcessController { manageRun() } class ThermalAnalysisRun { runAnalysis() } class ThermalCycleSimulator { coolingRate: Float peakTemperature: Float } class SafetyProtocol { emergencyStop: Boolean temperatureLimit: Float } class ResearchProject { principalInvestigator: String budget: Decimal } class ExperimentalDataset { integrityVerified: Boolean filterResults() } class SpectroscopyData { wavelength: Float emissionIntensity: Float } class MicrostructureAnalysis { correlateData() refinePhases() } class StressTestRunner { testType: String performTest() } class PerformanceMetric { load: Float incrementStep: Integer } class OptimizationResult { convergence: Float } class DesignConstraint { limitValue: Float } class RegulatoryStandard { limitValue: Float effectiveDate: Date } class ComplianceArchive { storeRecord() } class BatchRecord { primaryPhase: String qualityStatus: String } class CostEstimator { calculateExpenses() } class SupplierNetwork { findVendors() } class QualityAssurance { inspector: String isCertified: Boolean approveBatch() } class ReportGenerator { format: String compileReport() } AlloyBatch "1" *-- "0..*" MaterialSpecimen MaterialSpecimen "1" *-- "1" ElementComposition MaterialSpecimen "1" *-- "1" PhaseDistribution ExperimentPlanner ..> HeatTreatmentProfile : generates HeatTreatmentProfile ..> PhaseDiagramCalculator : validated by ProcessController "1" --> "0..*" ThermalAnalysisRun : manages ThermalAnalysisRun "1" --> "1" HeatTreatmentProfile : applies ThermalAnalysisRun ..> ThermalCycleSimulator : utilizes ThermalAnalysisRun ..> SafetyProtocol : adheres to ResearchProject "1" *-- "0..*" ExperimentalDataset ResearchProject "1" --> "0..*" DesignConstraint ExperimentalDataset "1" *-- "0..*" SpectroscopyData MicrostructureAnalysis ..> MaterialSpecimen : correlates MicrostructureAnalysis ..> SpectroscopyData : correlates MicrostructureAnalysis ..> PhaseDiagramCalculator : references StressTestRunner ..> MaterialSpecimen : tests StressTestRunner ..> PerformanceMetric : generates OptimizationResult ..> PerformanceMetric : fed by OptimizationResult --> ElementComposition : recommends ComplianceArchive "1" *-- "0..*" BatchRecord BatchRecord "0..*" --> "1" AlloyBatch BatchRecord "0..*" --> "1" RegulatoryStandard CostEstimator ..> ElementComposition : calculates from SupplierNetwork ..> DesignConstraint : meets QualityAssurance ..> AlloyBatch : approves ReportGenerator ..> PerformanceMetric : compiles ReportGenerator ..> QualityAssurance : compiles @enduml ``` # Choices Please choose from the following 3 options based on the scoring criteria: A. Response 1 is better. B. Response 2 is better. C. Tie. Please provide criterion-by-criterion scores before the final choice. Use Tie if the total scores are equal or the meaningful quality difference is small. Also, you should pay adequate and same attention to both responses. **Important**：You should act as an IMPARTIAL judge and be as OBJECTIVE as possible. AVOID ANY POSITION BIASES and ensure that the ORDER in which the responses were presented DOES NOT influence your decision. Before choosing A/B/C, first score Model 1 and Model 2 independently against each specific instruction. If the specific instruction provides a scoring scale, use that scale; otherwise use a 1-5 score where 1 means very poor alignment and 5 means excellent alignment. Base the final choice on the independent scores and the evidence, not on which model is shown first. # Output Your output should be in the following format: ```result Scores: 1. <criterion name>: Model 1 = <score>, Model 2 = <score>; Evidence: <concrete evidence from both models> 2. <criterion name>: Model 1 = <score>, Model 2 = <score>; Evidence: <concrete evidence from both models> Total: Model 1 = <total>, Model 2 = <total> Choice: A Reason: 1. Criterion name: compare Model 1 and Model 2 using concrete evidence from both models. 2. Criterion name: compare Model 1 and Model 2 using concrete evidence from both models. 3. Rejected or checked issues: mention any tempting but unsupported issue that you did not use for the decision, if relevant. 4. Overall judgment: explain why the chosen model is better, or why it is a tie. ``` | G2: llm | H2: GLM5.2 | I2: ```result Scores: 1. Requirement Alignment & Completeness: Model 1 = 5, Model 2 = 3; Evidence: Model 1 captures all requirements, explicitly modeling detailed classes like `StressTestRun` and `ProcessingStep` which are implied by the requirements. Model 1 also ensures both `DesignConstraint` and `RegulatoryStandard` have `effectiveDate` as required. Model 2 misses `effectiveDate` in `DesignConstraint`, and represents behaviors as methods (e.g., `generateProfile()`, `manageRun()`) rather than encapsulating the domain state and structure into distinct conceptual classes and attributes. 2. Associations, Cardinalities, and Relationship Types: Model 1 = 5, Model 2 = 2; Evidence: Model 1 correctly uses associations, compositions, and accurate multiplicities to reflect relationships (e.g., `AlloyBatch "1" *-- "1..*" MaterialSpecimen`, `ExperimentalDataset *-- MicrostructureAnalysis`). Model 2 relies heavily on dependency arrows (`..>`) instead of proper associations or aggregations for core domain relationships (e.g., `StressTestRunner ..> MaterialSpecimen`, `OptimizationResult ..> PerformanceMetric`). Furthermore, Model 2 attaches `ThermalCycleSimulator` and `SafetyProtocol` to `ThermalAnalysisRun` via dependencies, whereas the requirement states the `ProcessController` utilizes the simulator and adheres to protocols. 3. Clarity in Class Names and Attributes: Model 1 = 5, Model 2 = 3; Evidence: Model 1 provides rich attributes and uses Enumerations (e.g., `PhaseType`, `QualityStatus`) to ensure domain clarity. Class names are highly descriptive and align strictly with requirements. Model 2 lacks detail in several classes, using generic types like `Map` and `List` for `chemicalMakeup` and `processingSteps`. Classes like `MicrostructureAnalysis` and `PhaseDiagramCalculator` contain only methods without capturing their domain attributes. Total: Model 1 = 15, Model 2 = 8 Choice: A Reason: 1. Requirement Alignment & Completeness: Model 1 faithfully translates the requirement into an exhaustive domain model, ensuring no functionality is missed and avoiding hallucinations by using logically sound intermediate classes (e.g., `StressTestRun`, `CostEstimation`). Model 2 misses key attributes like `effectiveDate` for `DesignConstraint` and inappropriately converts structural requirements into methods. 2. Associations, Cardinalities, and Relationship Types: Model 1 demonstrates a strong understanding of UML relationship types, correctly applying compositions (e.g., for `MaterialSpecimen` and `PhaseDistribution`) and standard associations with proper cardinalities. Model 2's excessive use of dependency arrows (`..>`) instead of structural associations weakens the semantic representation of the domain significantly. 3. Clarity in Class Names and Attributes: Model 1's inclusion of enumerations and detailed attributes strictly mapped to the requirement text results in a much clearer and more professional software design compared to Model 2's sparse attributes and method-heavy approach. 4. Overall judgment: Model 1 is objectively better due to its comprehensive alignment with the requirements, proper use of UML semantics for associations, and higher clarity in class and attribute design. ``` | J2: A | K2: =IF(OR(J2="",C2="",E2=""),"",IF(J2="C","D(平局)",IF(J2=IF(E2="l2r","A","B"),LEFT(C2,1),RIGHT(C2,1)))) -> A | L2: A | M2: =IF(OR(K2="",L2=""),"",--(K2=L2)) -> 1
A3: AdvancedAlloyCompositionOptimization | B3: The Advanced Alloy Composition Optimization system supports research and industrial processes for developing high-performance metal alloys. The core unit of production is an Alloy Batch, created on a specific date, which contains multiple Material Specimens. Each specimen is defined by its density and surface finish, possesses a base Element Composition describing its chemical makeup, and has a current Phase Distribution detailing the fractions of target phases such as Austenite, Ferrite, Martensite, or Pearlite. Specimens can be analyzed to determine their current phase, classify grain structure, and annotate any defects. To achieve desired material properties, the system utilizes an Experiment Planner that generates Heat Treatment Profiles. These profiles, identified by name and quenching status, define processing steps and are validated before use. The planning process relies on a Phase Diagram Calculator to identify stable phases and check for equilibrium states. During execution, a Process Controller manages Thermal Analysis Runs, utilizing a Thermal Cycle Simulator to model cooling rates and peak temperatures while adhering to strict Safety Protocols that include emergency stop capabilities and temperature limits. Each thermal analysis run applies a specific profile. Data collection is organized under Research Projects, led by a principal investigator with a defined budget and associated design constraints. Projects encompass Experimental Datasets that verify data integrity, filter results, and store generated outcomes. These datasets aggregate Spectroscopy Data, which records wavelengths and emission intensities to detect phases and analyze elemental composition. Microstructure Analysis correlates specimen samples with spectroscopic data to refine phase distributions, utilizing the Phase Diagram Calculator as a reference. Furthermore, Stress Test Runners perform destructive or non-destructive tensile tests on specimens to generate Performance Metrics regarding load and increment steps. These metrics feed into Optimization Results that track convergence and recommend optimal element compositions. The system ensures adherence to engineering and legal standards through Design Constraints and Regulatory Standards, which specify limit values and effective dates to check specimen compliance. A Compliance Archive stores Batch Records, linking regulatory standards to specific batches; each record documents the primary phase, quality status, and the associated alloy batch. Operational support includes a Cost Estimator for calculating raw material expenses based on composition, a Supplier Network for finding vendors meeting design constraints, and a Quality Assurance module where certified inspectors approve batches. Finally, a Report Generator compiles performance metrics and quality assurance sources into summary reports in various formats. | C3: A vs B | D3: faithfulness | E3: r2l | F3: You are a professional software engineer with expertise across multiple domains. You evaluate UML class diagrams from the perspective of real-world software design, applying domain knowledge and engineering best practices alongside the provided scoring criteria. Please evaluate the two diagrams (Model 1, Model 2) based on the provided requirement and scoring criteria. # Criteria **CRITICAL INSTRUCTION**: You MUST evaluate the responses against EACH AND EVERY criterion listed in the "Specific Instructions" one by one. DO NOT aggregate, summarize, or skip any criterion. **Specific Instructions**: - Ensure that the design aligns with the given requirement strictly, achieving all the functionalities based on the requirements without making any hallucinations and additions. Ensure that the conceptual classes and their relationships accurately represent the essentials outlined in the requirement. This includes a detailed focus on the associations between classes, their cardinalities, and the types of relationships such as inheritance, aggregation, and composition. Clarity in class names and the optional inclusion of attributes are key for aligning with the project's vision. # Evaluation Guidelines ## General Rules - Consider only UML class diagram semantics (e.g., classes, attributes, associations, multiplicities, generalisation, composition/aggregation). - Ignore layout, styling, skinparams, comments, and notes. - If the response is incomplete or misses any required key component, regard it as a bad one. - Give credit for semantic clarity, but not for layout, comments, visibility markers, or other presentation-only differences. ## Forbidden Penalties (Strictly Enforced) You MUST NOT deduct points, lower scores, or claim a model is "worse", "complex", or "less practical" based on ANY of the following: 1. **Association Styles**: Using two opposite unidirectional associations (e.g., `A --> B` and `B --> A`) instead of one single bidirectional line (e.g., `A -- B`). They are 100% semantically equivalent. Treat opposite-direction associations as equivalent unless role labels, multiplicities, or navigability contradict the requirements. 2. **PlantUML Comments**: Using single-quote comments (e.g., `'opposite bank`) at the end of lines. These are standard tooling annotations — ignore them for scoring unless they obscure or contradict the relation meaning. 3. **Primitive Types**: Using common aliases for types (e.g., `int` instead of `Integer`, `str` instead of `String`, `boolean` instead of `Boolean`). Lowercase or language-flavored spellings are acceptable. 4. **Equivalent Multiplicity Literals**: Using `*` instead of `0..*`, or `1` instead of `1..1`. These pairs are semantically identical. 5. **Optional Abstractness**: Marking or not marking a superclass as `abstract` when the requirement does not say whether direct instances are allowed. Do not reward either style without requirement evidence. These forbidden factors must not appear as negative evidence under any criterion and must not affect criterion scores or the final choice. ## Evidence & Calibration Requirements - For every criterion you discuss, cite concrete evidence from both models. Quote or closely paraphrase the relevant class, attribute, association, multiplicity, inheritance, note, or missing element. - Do not claim a class, attribute, or association is missing when a synonymous or directly related element is present. If the present element is indirect, vague, over-constrained, or semantically weak, state that precise weakness instead. - Distinguish omissions from contradictions. Missing a hard constraint is usually less severe than explicitly modeling the opposite or an invalid multiplicity. - Do not reward a simpler model merely for being shorter if the more detailed model uses traceable intermediate workflow/concept classes required for domain reasoning. - Do not penalize a detailed model merely for using transparent refinements such as `Definition`, `Placement`, `Entry`, `Session`, `State`, `Record`, `Assignment`, `Arrangement`, or `Need` when the base requirement term remains recognizable. - Do not reward extra identifiers, timestamps, statuses, classes, or implementation-oriented detail unless they improve coverage of a stated requirement fact. - Text introduced by `e.g.`, `for example`, or `such as` gives examples, not a complete enumeration, unless the requirement explicitly declares a closed list. - Keep UML/PlantUML standards separate from domain accuracy. Domain-faithfulness problems, wrong business multiplicities, missing constraints, or vague semantics belong under the domain criteria, not UML standards, unless they make the notation invalid or unreadable. - When evaluating position bias, remember that Model 1 and Model 2 may be swapped in a second pass. Use only the content under each model block, not assumptions from prior comparisons or labels. # Requirement ``` The Advanced Alloy Composition Optimization system supports research and industrial processes for developing high-performance metal alloys. The core unit of production is an Alloy Batch, created on a specific date, which contains multiple Material Specimens. Each specimen is defined by its density and surface finish, possesses a base Element Composition describing its chemical makeup, and has a current Phase Distribution detailing the fractions of target phases such as Austenite, Ferrite, Martensite, or Pearlite. Specimens can be analyzed to determine their current phase, classify grain structure, and annotate any defects. To achieve desired material properties, the system utilizes an Experiment Planner that generates Heat Treatment Profiles. These profiles, identified by name and quenching status, define processing steps and are validated before use. The planning process relies on a Phase Diagram Calculator to identify stable phases and check for equilibrium states. During execution, a Process Controller manages Thermal Analysis Runs, utilizing a Thermal Cycle Simulator to model cooling rates and peak temperatures while adhering to strict Safety Protocols that include emergency stop capabilities and temperature limits. Each thermal analysis run applies a specific profile. Data collection is organized under Research Projects, led by a principal investigator with a defined budget and associated design constraints. Projects encompass Experimental Datasets that verify data integrity, filter results, and store generated outcomes. These datasets aggregate Spectroscopy Data, which records wavelengths and emission intensities to detect phases and analyze elemental composition. Microstructure Analysis correlates specimen samples with spectroscopic data to refine phase distributions, utilizing the Phase Diagram Calculator as a reference. Furthermore, Stress Test Runners perform destructive or non-destructive tensile tests on specimens to generate Performance Metrics regarding load and increment steps. These metrics feed into Optimization Results that track convergence and recommend optimal element compositions. The system ensures adherence to engineering and legal standards through Design Constraints and Regulatory Standards, which specify limit values and effective dates to check specimen compliance. A Compliance Archive stores Batch Records, linking regulatory standards to specific batches; each record documents the primary phase, quality status, and the associated alloy batch. Operational support includes a Cost Estimator for calculating raw material expenses based on composition, a Supplier Network for finding vendors meeting design constraints, and a Quality Assurance module where certified inspectors approve batches. Finally, a Report Generator compiles performance metrics and quality assurance sources into summary reports in various formats. ``` # Model 1 ``` @startuml skinparam classAttributeIconSize 0 hide empty members class AlloyBatch { creationDate: Date } class MaterialSpecimen { density: Float surfaceFinish: String } class ElementComposition { chemicalMakeup: Map } class PhaseDistribution { austenite: Float ferrite: Float martensite: Float pearlite: Float } class ExperimentPlanner { generateProfile() } class HeatTreatmentProfile { name: String quenchingStatus: Boolean processingSteps: List isValidated: Boolean } class PhaseDiagramCalculator { identifyStablePhases() checkEquilibrium() } class ProcessController { manageRun() } class ThermalAnalysisRun { runAnalysis() } class ThermalCycleSimulator { coolingRate: Float peakTemperature: Float } class SafetyProtocol { emergencyStop: Boolean temperatureLimit: Float } class ResearchProject { principalInvestigator: String budget: Decimal } class ExperimentalDataset { integrityVerified: Boolean filterResults() } class SpectroscopyData { wavelength: Float emissionIntensity: Float } class MicrostructureAnalysis { correlateData() refinePhases() } class StressTestRunner { testType: String performTest() } class PerformanceMetric { load: Float incrementStep: Integer } class OptimizationResult { convergence: Float } class DesignConstraint { limitValue: Float } class RegulatoryStandard { limitValue: Float effectiveDate: Date } class ComplianceArchive { storeRecord() } class BatchRecord { primaryPhase: String qualityStatus: String } class CostEstimator { calculateExpenses() } class SupplierNetwork { findVendors() } class QualityAssurance { inspector: String isCertified: Boolean approveBatch() } class ReportGenerator { format: String compileReport() } AlloyBatch "1" *-- "0..*" MaterialSpecimen MaterialSpecimen "1" *-- "1" ElementComposition MaterialSpecimen "1" *-- "1" PhaseDistribution ExperimentPlanner ..> HeatTreatmentProfile : generates HeatTreatmentProfile ..> PhaseDiagramCalculator : validated by ProcessController "1" --> "0..*" ThermalAnalysisRun : manages ThermalAnalysisRun "1" --> "1" HeatTreatmentProfile : applies ThermalAnalysisRun ..> ThermalCycleSimulator : utilizes ThermalAnalysisRun ..> SafetyProtocol : adheres to ResearchProject "1" *-- "0..*" ExperimentalDataset ResearchProject "1" --> "0..*" DesignConstraint ExperimentalDataset "1" *-- "0..*" SpectroscopyData MicrostructureAnalysis ..> MaterialSpecimen : correlates MicrostructureAnalysis ..> SpectroscopyData : correlates MicrostructureAnalysis ..> PhaseDiagramCalculator : references StressTestRunner ..> MaterialSpecimen : tests StressTestRunner ..> PerformanceMetric : generates OptimizationResult ..> PerformanceMetric : fed by OptimizationResult --> ElementComposition : recommends ComplianceArchive "1" *-- "0..*" BatchRecord BatchRecord "0..*" --> "1" AlloyBatch BatchRecord "0..*" --> "1" RegulatoryStandard CostEstimator ..> ElementComposition : calculates from SupplierNetwork ..> DesignConstraint : meets QualityAssurance ..> AlloyBatch : approves ReportGenerator ..> PerformanceMetric : compiles ReportGenerator ..> QualityAssurance : compiles @enduml ``` # Model 2 ``` @startuml ' Enumerations enum SurfaceFinish { POLISHED ROUGH MACHINED AS_CAST } enum PhaseType { AUSTENITE FERRITE MARTENSITE PEARLITE } enum TestType { DESTRUCTIVE NON_DESTRUCTIVE } enum QualityStatus { APPROVED REJECTED PENDING } enum RunState { INITIALIZED HEATING HOLDING COOLING COMPLETED EMERGENCY_STOP } enum ReportFormat { PDF CSV JSON HTML } ' Domain Classes class AlloyBatch { batchId: String creationDate: Date name: String } class MaterialSpecimen { specimenId: String density: double surfaceFinish: SurfaceFinish grainStructure: String defectAnnotation: String } class ElementComposition { elementName: String percentage: double } class PhaseDistribution { phaseType: PhaseType fraction: double } class ExperimentPlanner { plannerId: String name: String } class HeatTreatmentProfile { profileId: String name: String quenchingStatus: boolean isValidated: boolean } class ProcessingStep { stepOrder: int targetTemperature: double durationMinutes: int description: String } class PhaseDiagramCalculator { calculatorId: String name: String equilibriumState: boolean stablePhases: String } class ProcessController { controllerId: String name: String } class ThermalAnalysisRun { runId: String currentState: RunState peakTemperature: double coolingRate: double startTime: Date endTime: Date } class ThermalCycleSimulator { simulatorId: String name: String } class SafetyProtocol { protocolId: String maxTemperatureLimit: double minTemperatureLimit: double emergencyStopEnabled: boolean } class ResearchProject { projectId: String projectName: String principalInvestigator: String budget: double } class ExperimentalDataset { datasetId: String name: String dataIntegrityVerified: boolean creationDate: Date filterCriteria: String resultsFiltered: boolean } class SpectroscopyData { dataId: String wavelength: double emissionIntensity: double detectedPhase: PhaseType timestamp: Date } class MicrostructureAnalysis { analysisId: String correlatedPhase: PhaseType refinedFraction: double description: String } class StressTestRunner { runnerId: String name: String } class StressTestRun { testId: String testType: TestType maxLoad: double incrementStep: double timestamp: Date } class PerformanceMetric { metricId: String loadValue: double incrementValue: double stressValue: double strainValue: double } class OptimizationResult { resultId: String convergenceTracked: boolean iterationCount: int recommendedComposition: String } class DesignConstraint { constraintId: String constraintName: String limitValue: double effectiveDate: Date } class RegulatoryStandard { standardId: String standardName: String limitValue: double effectiveDate: Date } class ComplianceArchive { archiveId: String archiveDate: Date } class BatchRecord { recordId: String primaryPhase: PhaseType qualityStatus: QualityStatus recordDate: Date } class CostEstimator { estimatorId: String name: String } class CostEstimation { estimationId: String totalCost: double currency: String calculationDate: Date } class SupplierNetwork { networkId: String name: String } class Supplier { supplierId: String name: String meetsConstraints: boolean contactInfo: String } class QualityAssurance { moduleId: String name: String } class QualityAssuranceReview { reviewId: String inspectorName: String inspectorCertified: boolean approvalDate: Date isApproved: boolean } class ReportGenerator { generatorId: String name: String } class SummaryReport { reportId: String title: String format: ReportFormat generationDate: Date } ' Associations and Compositions AlloyBatch "1" *-- "1..*" MaterialSpecimen: contains specimens MaterialSpecimen "1" *-- "1..*" ElementComposition: base composition MaterialSpecimen "1" *-- "1..*" PhaseDistribution: current phases ExperimentPlanner "1" --> "1..*" HeatTreatmentProfile: generates profiles HeatTreatmentProfile "1" *-- "1..*" ProcessingStep: defined steps PhaseDiagramCalculator "1" --> "*" HeatTreatmentProfile: references for planning PhaseDiagramCalculator "1" --> "*" MicrostructureAnalysis: references for analysis ProcessController "1" --> "1..*" ThermalAnalysisRun: manages runs ProcessController "1" --> "1" ThermalCycleSimulator: utilizes simulator ProcessController "1" --> "1..*" SafetyProtocol: adheres to protocols ThermalCycleSimulator "1" --> "*" ThermalAnalysisRun: simulates ThermalAnalysisRun "*" --> "1" HeatTreatmentProfile: applies profile ResearchProject "1" *-- "1..*" ExperimentalDataset: encompassed datasets ResearchProject "1" --> "1..*" DesignConstraint: associated constraints ExperimentalDataset "1" *-- "*" SpectroscopyData: aggregated data ExperimentalDataset "1" *-- "*" MicrostructureAnalysis: included analyses MicrostructureAnalysis "*" --> "1" MaterialSpecimen: correlates specimen MicrostructureAnalysis "*" --> "1" SpectroscopyData: correlates spectroscopic data StressTestRunner "1" --> "1..*" StressTestRun: performs tests MaterialSpecimen "1" --> "*" StressTestRun: tested in StressTestRun "1" *-- "1..*" PerformanceMetric: generated metrics PerformanceMetric "*" --> "1" OptimizationResult: feeds into ComplianceArchive "1" *-- "1..*" BatchRecord: stored records BatchRecord "*" --> "1" AlloyBatch: documents batch BatchRecord "*" --> "1..*" RegulatoryStandard: linked standards CostEstimator "1" --> "*" AlloyBatch: estimates costs for CostEstimator "1" --> "*" ElementComposition: calculates based on CostEstimator "1" --> "*" CostEstimation: produces estimations AlloyBatch "1" --> "1" CostEstimation: estimated by SupplierNetwork "1" --> "*" Supplier: finds vendors SupplierNetwork "1" --> "*" DesignConstraint: matches constraints QualityAssurance "1" --> "*" QualityAssuranceReview: conducts reviews AlloyBatch "1" --> "*" QualityAssuranceReview: reviewed in ReportGenerator "1" --> "*" SummaryReport: compiles reports ReportGenerator "*" --> "*" PerformanceMetric: compiles from metrics ReportGenerator "*" --> "*" QualityAssuranceReview: compiles from reviews @enduml ``` # Choices Please choose from the following 3 options based on the scoring criteria: A. Response 1 is better. B. Response 2 is better. C. Tie. Please provide criterion-by-criterion scores before the final choice. Use Tie if the total scores are equal or the meaningful quality difference is small. Also, you should pay adequate and same attention to both responses. **Important**：You should act as an IMPARTIAL judge and be as OBJECTIVE as possible. AVOID ANY POSITION BIASES and ensure that the ORDER in which the responses were presented DOES NOT influence your decision. Before choosing A/B/C, first score Model 1 and Model 2 independently against each specific instruction. If the specific instruction provides a scoring scale, use that scale; otherwise use a 1-5 score where 1 means very poor alignment and 5 means excellent alignment. Base the final choice on the independent scores and the evidence, not on which model is shown first. # Output Your output should be in the following format: ```result Scores: 1. <criterion name>: Model 1 = <score>, Model 2 = <score>; Evidence: <concrete evidence from both models> 2. <criterion name>: Model 1 = <score>, Model 2 = <score>; Evidence: <concrete evidence from both models> Total: Model 1 = <total>, Model 2 = <total> Choice: A Reason: 1. Criterion name: compare Model 1 and Model 2 using concrete evidence from both models. 2. Criterion name: compare Model 1 and Model 2 using concrete evidence from both models. 3. Rejected or checked issues: mention any tempting but unsupported issue that you did not use for the decision, if relevant. 4. Overall judgment: explain why the chosen model is better, or why it is a tie. ``` | G3: llm | H3: GLM5.2 | I3: ```result Scores: 1. Alignment with requirement: Model 1 = 4, Model 2 = 4; Evidence: M1 misses the `effectiveDate` attribute on `DesignConstraint` despite the requirement stating both Design Constraints and Regulatory Standards specify limit values and effective dates. M2 models the `recommendedComposition` as a String attribute in `OptimizationResult` rather than creating an association to `ElementComposition` as requested by "recommend optimal element compositions", whereas M1 correctly links them (`OptimizationResult --> ElementComposition : recommends`). 2. Conceptual classes and relationships: Model 1 = 3, Model 2 = 5; Evidence: M1 uses dashed dependencies (`..>`) for structural and generative relationships (e.g., `ExperimentPlanner ..> HeatTreatmentProfile : generates`, `ReportGenerator ..> PerformanceMetric : compiles`), which is semantically weak for class diagrams. M2 properly extracts implicit concepts into structural classes like `ProcessingStep`, `StressTestRun`, `SummaryReport`, and `Supplier`, using standard associations to model them (e.g., `HeatTreatmentProfile "1" *-- "1..*" ProcessingStep`). 3. Associations, cardinalities, and relationship types: Model 1 = 3, Model 2 = 5; Evidence: M1 consistently uses dependency arrows for what should be compositions or associations, failing to accurately represent structural containment (e.g., `StressTestRunner ..> PerformanceMetric : generates`). M2 correctly uses directed associations and compositions with appropriate multiplicities (e.g., `StressTestRun "1" *-- "1..*" PerformanceMetric: generated metrics`, `ComplianceArchive "1" *-- "1..*" BatchRecord: stored records`). 4. Clarity in class names and attributes: Model 1 = 4, Model 2 = 5; Evidence: M1 has reasonable class names and attributes, though `processingSteps: List` is less clear than a dedicated class. M2 provides better domain clarity by introducing enumerations (e.g., `PhaseType`, `TestType`, `QualityStatus`) and breaking down complex properties into typed attributes and classes, strictly adhering to standard UML modeling practices. Total: Model 1 = 14, Model 2 = 19 Choice: B Reason: 1. Alignment with requirement: Model 1 missed the `effectiveDate` for `DesignConstraint`, while Model 2 missed the association from `OptimizationResult` to `ElementComposition`. Thus, both have minor omissions regarding specific requirement details. 2. Conceptual classes and relationships: Model 2 is vastly superior in representing the essentials because it extracts the requirement's implicit classes (e.g., `ProcessingStep`, `StressTestRun`, `SummaryReport`) and establishes proper structural links, whereas Model 1 relies heavily on dependency arrows (`..>`) which are inappropriate for capturing structural composition and generation in a class diagram. 3. Rejected or checked issues: M2's introduction of intermediate classes like `QualityAssuranceReview` and `CostEstimation` were checked to ensure they weren't hallucinations; they align strictly with "certified inspectors approve batches" and "calculating raw material expenses". This is a transparent and valid refinement, not an unsupported addition. 4. Overall judgment: Model 2 is better because it adheres to proper UML class diagram semantics by using associations and compositions to represent structural relationships, and it correctly models the implicit sub-components of the domain, whereas Model 1's diagram is dominated by dependency arrows that fail to represent the actual architectural structure of the system. ``` | J3: B | K3: =IF(OR(J3="",C3="",E3=""),"",IF(J3="C","D(平局)",IF(J3=IF(E3="l2r","A","B"),LEFT(C3,1),RIGHT(C3,1)))) -> A | L3: A | M3: =IF(OR(K3="",L3=""),"",--(K3=L3)) -> 1
